Workbook

Sheet 基本信息
A1: 基本信息
A2: 序号 | B2: 项目 | C2: 原名称 | D2: 数值 | E2: 单位 | F2: 关键词 | G2: 辅助关键词 | H2: 是否必须 | I2: 选项 | J2: 备注 | K2: 关联指标
A3: 1 | B3: 项目运营起始年 | C3: 项目运营起始年 | E3: - | J3: 人工填
A4: 2 | B4: 交流测装机容量 | C4: 交流测装机容量 | E4: MW | F4: 交流侧容量、交流侧装机容量、交流容量、建设装机容量、建设容量 | G4: MW | H4: 是
A5: 3 | B5: 直流侧装机容量或装机/规划容量 | C5: 直流侧装机容量 | E5: MWp | F5: 直流侧装机容量、装机容量、规划容量、总容量 | G5: MWp | H5: 是
A6: 4 | B6: 静态投资 | C6: 静态投资 | E6: 万元 | F6: 静态投资、静态 | G6: 万 | H6: 是
A7: 5 | B7: 建设期利息 | C7: 建设期利息 | E7: 万元 | F7: 建设期利息 | G7: 万 | H7: 是
A8: 6 | B8: 可抵扣税金 | C8: 可抵扣税金 | E8: 万元 | F8: 可抵扣、增值税、可抵扣税金、增值税抵扣、可抵扣增值税 | G8: 万 | H8: 否
A9: 7 | B9: 首年无衰减利用小时 | C9: 首年无衰减利用小时 | E9: h | F9: 首年年利用小时数、利用小时数、首年、首年利用小时 | G9: h | H9: 否
A10: 8 | B10: 本项目光伏组件类型 | C10: 组件类型 | E10: - | F10: N型、P型、单玻、双玻、多晶、P型单玻、P型双玻、N型单玻、N型双玻、多晶单玻、多晶双玻 | H10: 是 | I10: P型单玻、P型双玻、N型单玻、N型双玻、多晶单玻、多晶双玻
A11: 9 | B11: 所在地区 | C11: 所在地区 | D11: 天津 | E11: - | F11: 发电项目、项目所在地、本工程位于、本项目位于、省、市 | I11: 北京、天津、河北冀北地区、河北冀南地区、山西、辽宁、吉林延边自治州外地区、黑龙江、上海、江苏、浙江、安徽、福建、江西赣州市外地区、山东、河南、湖北恩施自治州外地区、湖南湘西自治州外地区、广东、海南、江西赣州市、湖南湘西自治州、湖北恩施自治州、吉林延边自治州、广西、内蒙古蒙东地区、内蒙古蒙西地区、重庆、四川、贵州、云南、西藏、陕西、甘肃、青海、宁夏、新疆
A12: 10 | B12: 电价电量取值标准 | C12: 电价电量取值标准 | E12: - | I12: 标准1、标准2 | J12: 人工填
A13: 11 | B13: 运维方式 | C13: 运维方式 | D13: 自主运维 | E13: - | F13: 委托运维、外委、运维 | H13: 是 | I13: 自主运维、委托运维
A14: 12 | B14: 本项目光伏组件运行方式 | C14: 跟踪方式 | E14: - | F14: 固定式、固定可调、跟踪式 | G14: 本项目、本工程 | H14: 否 | I14: 固定式、固定可调、跟踪式
A15: 13 | B15: 建设/项目地的地形类型 | C15: 地质环境 | E15: - | F15: 地形、地貌、地形地貌、平原、山地、丘陵、水面、鱼塘、渔塘 | G15: 本项目、建设场地、本工程、建设地 | H15: 否 | I15: 平原、山地、水面
A16: 14 | B16: 集电线路长度 | C16: 集电线路长度 | E16: km | F16: 集电线路、35kv | G16: 35kv | H16: 否
A17: 15 | B17: 光伏子阵容量 | C17: 光伏子阵 | D17: 2MW以上 | E17: MW | F17: 光伏子阵、光伏阵列、光伏单元、光伏发电单元 | H17: 否 | K17: 直流侧装机容量或装机/规划容量
A18: 16 | B18: 项目海拔高度 | C18: 海拔高度 | E18: m | F18: 海拔、高程 | G18: m | H18: 是
A19: 17 | B19: 新建、配套建设升压站（变电站）电压等级 | C19: 升压变电站 | E19: kv | F19: 升压站、变电站、开关站 | G19: 新建 | H19: 是
A20: 18 | B20: 其他费用1 | C20: 其他费用1 | E20: 万元/年 | F20: 房屋租金、屋顶租金、房屋租赁、屋顶租赁 | H20: 是
A21: 19 | B21: 其他费用2 | C21: 其他费用2 | E21: 万元/年 | F21: 土地租金、土地租赁 | H21: 是
A22: 20 | B22: 其他费用3 | C22: 其他费用3 | E22: 万元/年 | F22: 储能租金、储能租赁 | H22: 是
A23: 21 | B23: 平均上网电价 | E23: 元/(kW•h) | F23: 电价、上网电价 | G23: 元/(kW•h) | H23: 是
A24: 22 | B24: 平均弃电率 | E24: % | F24: 弃电 | G24: % | H24: 是

Sheet 地区辅助页
A1: 序号 | B1: 填写地区 | D1: 电价电量地区 | E1: =_xlfn.XLOOKUP(基本信息!D11,B:B,D:D,"",0) -> 天津 | G1: 人工成本区域 | H1: =_xlfn.XLOOKUP(基本信息!D11,B:B,G:G,"",0) -> 华北
A2: 1 | B2: 北京 | D2: 北京 | G2: 华北
A3: =A2+1 -> 2 | B3: 天津 | D3: 天津 | G3: 华北
A4: =A3+1 -> 3 | B4: 河北冀北地区 | D4: 冀北 | G4: 华北
A5: =A4+1 -> 4 | B5: 河北冀南地区 | D5: 冀南 | G5: 华北
A6: =A5+1 -> 5 | B6: 山西 | D6: 山西 | G6: 华北
A7: =A6+1 -> 6 | B7: 辽宁 | D7: 辽宁 | G7: 东北
A8: =A7+1 -> 7 | B8: 吉林延边自治州外地区 | D8: 吉林 | G8: 东北
A9: =A8+1 -> 8 | B9: 黑龙江 | D9: 黑龙江 | G9: 东北
A10: =A9+1 -> 9 | B10: 上海 | D10: 上海 | G10: 华东
A11: =A10+1 -> 10 | B11: 江苏 | D11: 江苏 | G11: 华东
A12: =A11+1 -> 11 | B12: 浙江 | D12: 浙江 | G12: 华东
A13: =A12+1 -> 12 | B13: 安徽 | D13: 安徽 | G13: 华东
A14: =A13+1 -> 13 | B14: 福建 | D14: 福建 | G14: 华东
... A38: =A37+1 -> 37 | B38: 新疆 | D38: 新疆 | G38: 西北

Sheet 成本费用取值表
B1: 修理费
B2: 序号 | C2: 项目名称 | D2: 建议值(元/KW) | E2: 按装机容量修正（兆瓦） | J2: 集电线路长度（公里） | L2: 按组件类型修正 | O2: 按跟踪方式修正 | Q2: 按地质环境修正 | U2: 按上年度是否亏损修正 | W2: 按是否出质保期修正 | Y2: 检修业务是否外委
E3: 10（含）以下 | F3: 10-50（含） | G3: 50-100（含） | H3: 100-300（含） | I3: 300以上 | J3: 20（含）以下 | K3: 20-50（含） | L3: 单晶 | M3: 多晶 | N3: 薄膜 | O3: 固定 | P3: 斜/平单轴 | Q3: 平原及其它 | R3: 山地丘陵及沙地 | S3: 屋顶 | T3: 水面 | U3: 亏损企业 | V3: 赢利企业 | W3: 期内 | X3: 期外 | Y3: 是 | Z3: 否
B4: 1 | C4: 发电设备 | D4: 22.4 | E4: 1.05 | F4: 1 | G4: 0.95 | H4: 0.9 | I4: 0.9 | J4: 1 | K4: 1 | L4: 1 | M4: 1 | N4: 1.2 | O4: 1 | P4: 1.2 | Q4: 1 | R4: 1.05 | S4: 1.1 | T4: 1.2 | U4: 0.95 | V4: 1 | W4: 0.15 | X4: 1 | Y4: 0.05 | Z4: 1
B5: 2 | C5: 升压站 | D5: 3.2 | E5: 1 | F5: 1 | G5: 0.95 | H5: 0.9 | I5: 0.9 | J5: 1 | K5: 1 | L5: 1 | M5: 1 | N5: 1 | O5: 1 | P5: 1 | Q5: 1 | R5: 1 | S5: 1 | T5: 1 | U5: 0.95 | V5: 1 | W5: 1 | X5: 1 | Y5: 0.05 | Z5: 1
B6: 3 | C6: 中控室 | D6: 0.64 | E6: 1 | F6: 1 | G6: 1 | H6: 1 | I6: 1 | J6: 1 | K6: 1 | L6: 1 | M6: 1 | N6: 1 | O6: 1 | P6: 1 | Q6: 1 | R6: 1 | S6: 1 | T6: 1 | U6: 0.95 | V6: 1 | W6: 0.7 | X6: 1 | Y6: 0.05 | Z6: 1
B7: 4 | C7: 输配电及线路 | D7: 3.2 | E7: 1 | F7: 1 | G7: 0.95 | H7: 0.9 | I7: 0.9 | J7: 1.1 | K7: 1.2 | L7: 1 | M7: 1 | N7: 1 | O7: 1 | P7: 1 | Q7: 1 | R7: 1 | S7: 1 | T7: 1 | U7: 0.95 | V7: 1 | W7: 0.7 | X7: 1 | Y7: 0.05 | Z7: 1
B8: 5 | C8: 生产非生产建筑物 | D8: 2.56 | E8: 1 | F8: 1 | G8: 1 | H8: 1 | I8: 1 | J8: 1 | K8: 1 | L8: 1 | M8: 1 | N8: 1 | O8: 1 | P8: 1 | Q8: 1 | R8: 1 | S8: 1 | T8: 1 | U8: 0.95 | V8: 1 | W8: 1 | X8: 1 | Y8: 0.05 | Z8: 1
C9: 小计 | D9: 32 | E9: 33.12 | F9: 32 | G9: 30.56 | H9: 29.12 | I9: 29.12 | J9: 32.32 | K9: 32.64 | L9: 32 | M9: 32 | N9: 36.48 | O9: 32 | P9: 36.48 | Q9: 32 | R9: 33.12 | S9: 34.24 | T9: 36.48 | U9: 30.4 | V9: 32 | W9: 11.808 | X9: 32 | Y9: 1.6 | Z9: 32
C10: =IF(SUM(E10:V10)+SUM(Y10:Z10)=7,"正确","错误") -> #REF! | E10: =IF(基本参数!$B$7<=10,1,0) -> 1 | F10: =IF(AND(基本参数!$B$7>10,基本参数!$B$7<=50),1,0) -> 0 | G10: =IF(AND(基本参数!$B$7>50,基本参数!$B$7<=100),1,0) -> 0 | H10: =IF(AND(基本参数!$B$7>100,基本参数!$B$7<=300),1,0) -> 0 | I10: =IF(基本参数!$B$6>300,1,0) -> 0 | J10: =IF(基本信息!$D$15=J3,1,0) -> 0 | K10: =IF(基本信息!$D$15=K3,1,0) -> 0 | L10: =IF(M10+N10=0,1,0) -> 1 | M10: =IF(OR(收入和税金!C5="多晶单玻",收入和税金!C5="多晶双玻"),1,0) -> 0 | O10: =P45+Q45 -> #REF! | P10: =R45 -> #REF! | Q10: =IF(基本信息!#REF!=Q3,1,0) -> #REF! | R10: =IF(基本信息!#REF!=R3,1,0) -> #REF! | S10: =IF(基本信息!#REF!=S3,1,0) -> #REF! | T10: =IF(基本信息!#REF!=T3,1,0) -> #REF! | V10: 1 | Z10: 1
C11: XXMW维修费
C12: 质保期内 | D12: 质保期外
C13: =D4*W4*SUMPRODUCT(Y4:Z4,$Y$10:$Z$10) -> 3.36 | D13: =D4*X4*SUMPRODUCT(Y4:Z4,$Y$10:$Z$10)*SUMPRODUCT(E4:I4,$E$10:$I$10)*SUMPRODUCT(J4:K4,$J$10:$K$10)*SUMPRODUCT(L4:N4,$L$10:$N$10)*SUMPRODUCT(O4:P4,$O$10:$P$10)*SUMPRODUCT(Q4:T4,$Q$10:$T$10)*SUMPRODUCT(U4:V4,$U$10:$V$10) -> #REF!
C14: =SUMPRODUCT(F70:R70,F71:R71) -> 0 | D14: =D5*X5*SUMPRODUCT(Y5:Z5,$Y$10:$Z$10)*SUMPRODUCT(E5:I5,$E$10:$I$10)*SUMPRODUCT(J5:K5,$J$10:$K$10)*SUMPRODUCT(L5:N5,$L$10:$N$10)*SUMPRODUCT(O5:P5,$O$10:$P$10)*SUMPRODUCT(Q5:T5,$Q$10:$T$10)*SUMPRODUCT(U5:V5,$U$10:$V$10) -> #REF! | G14: 质保期 | H14: 10
C15: =SUMPRODUCT(F71:R71,F72:R72) -> 0 | D15: =D6*X6*SUMPRODUCT(Y6:Z6,$Y$10:$Z$10)*SUMPRODUCT(E6:I6,$E$10:$I$10)*SUMPRODUCT(J6:K6,$J$10:$K$10)*SUMPRODUCT(L6:N6,$L$10:$N$10)*SUMPRODUCT(O6:P6,$O$10:$P$10)*SUMPRODUCT(Q6:T6,$Q$10:$T$10)*SUMPRODUCT(U6:V6,$U$10:$V$10) -> #REF!
C16: =SUMPRODUCT(F72:R72,F73:R73) -> 0 | D16: =D7*X7*SUMPRODUCT(Y7:Z7,$Y$10:$Z$10)*SUMPRODUCT(E7:I7,$E$10:$I$10)*SUMPRODUCT(J7:K7,$J$10:$K$10)*SUMPRODUCT(L7:N7,$L$10:$N$10)*SUMPRODUCT(O7:P7,$O$10:$P$10)*SUMPRODUCT(Q7:T7,$Q$10:$T$10)*SUMPRODUCT(U7:V7,$U$10:$V$10) -> #REF!
C17: =SUMPRODUCT(F73:R73,F74:R74) -> 0 | D17: =D8*X8*SUMPRODUCT(Y8:Z8,$Y$10:$Z$10)*SUMPRODUCT(E8:I8,$E$10:$I$10)*SUMPRODUCT(J8:K8,$J$10:$K$10)*SUMPRODUCT(L8:N8,$L$10:$N$10)*SUMPRODUCT(O8:P8,$O$10:$P$10)*SUMPRODUCT(Q8:T8,$Q$10:$T$10)*SUMPRODUCT(U8:V8,$U$10:$V$10) -> #REF!
C18: =SUM(C13:C17) -> 3.36 | D18: =SUM(D13:D17) -> #REF!
B21: 材料费
B22: 项目名称 | C22: 建议值(元/KW) | D22: 按装机容量修正（兆瓦） | I22: 按机组类型修正 | L22: 按跟踪方式修正 | N22: 按地质环境修正 | R22: 按上年度是否亏损修正 | T22: 按是否出质保期修正 | V22: 日常维护及运行外委
D23: 10（含）以下 | E23: 10-50（含） | F23: 50-100（含） | G23: 100-300（含） | H23: 300以上 | I23: 单晶 | J23: 多晶 | K23: 薄膜 | L23: 固定 | M23: 平/斜单轴 | N23: 平原及其它 | O23: 山地丘陵及沙地 | P23: 屋顶 | Q23: 水面 | R23: 亏损企业 | S23: 赢利企业 | T23: 期内 | U23: 期外 | V23: 是 | W23: 否
B24: 基准值 | C24: 8 | D24: 1.05 | E24: 1 | F24: 0.85 | G24: 0.7 | H24: 0.6 | I24: 1 | J24: 1 | K24: 1.2 | L24: 1 | M24: 1.2 | N24: 1 | O24: 1.05 | P24: 1.1 | Q24: 1.2 | R24: 0.95 | S24: 1 | T24: 0.5 | U24: 1 | V24: 0.05 | W24: 1
D25: =E10 -> 1 | E25: =F10 -> 0 | F25: =G10 -> 0 | G25: =H10 -> 0 | H25: =I10 -> 0 | I25: =L10 -> 1 | J25: =M10 -> 0 | K25: =N10 -> 0 | L25: =O10 -> #REF! | M25: =P10 -> #REF! | N25: =Q10 -> #REF! | O25: =R10 -> #REF! | P25: =S10 -> #REF! | ... S25: =V10 -> 1 | V25: =Y10 -> 0 | W25: =Z10 -> 1
C26: XXMW材料费
C27: 质保期内 | D27: 质保期外
C28: =C24*T24*SUMPRODUCT(V24:W24,V25:W25) -> 4 | D28: =C24*U24*SUMPRODUCT(D24:H24,D25:H25)*SUMPRODUCT(I24:K24,I25:K25)*SUMPRODUCT(L24:M24,L25:M25)*SUMPRODUCT(N24:Q24,N25:Q25)*SUMPRODUCT(R24:S24,R25:S25)*SUMPRODUCT(V24:W24,V25:W25) -> #REF!
B31: 其他费用
B32: 项目名称 | C32: 建议值 (元/KW) | D32: 按装机容量修正（兆瓦） | I32: 全场外委
D33: 10（含）以下 | E33: 10-50（含） | F33: 50-100（含） | G33: 100-300（含） | H33: 300以上 | I33: 是 | J33: 否
B34: 基准值 | C34: 40 | D34: 1.5 | E34: 1 | F34: 0.8 | G34: 0.6 | H34: 0.4 | I34: 0.8 | J34: 1
D35: =D25 -> 1 | E35: =E25 -> 0 | F35: =F25 -> 0 | G35: =G25 -> 0 | H35: =H25 -> 0 | I35: =V25 -> 0 | J35: =W25 -> 1
C36: XXMW其他费用
C37: =C34*SUMPRODUCT(D34:H34,D35:H35)*SUMPRODUCT(I34:J34,I35:J35) -> 60
B41: 委托运维费
B42: 项目名称 | C42: 建议值(元/kW) | D42: 按装机容量修正（兆瓦） | K42: 光伏子阵修正 | N42: 按容配比修正 | P42: 按跟踪方式修正 | S42: 按地质环境修正 | U42: 按海拔高度修正 | W42: 是否含升压变电站 | AB42: 投产年限修正
D43: 10(含）以下 | E43: 10-20（含） | F43: 20-40（含） | G43: 40-60（含） | H43: 60-80（含） | I43: 80-100（含） | J43: 100以上 | K43: 1MW以下（含） | L43: 1MW-2MW（含） | M43: 2MW以上 | N43: 1.05（含）以下 | O43: 1.05以上 | P43: 固定式 | Q43: 固定可调 | R43: 跟踪式 | S43: 平原及其它 | T43: 山地、戈壁、沙漠、水面、屋顶 | U43: 海拔2500米及以上 | V43: 海拔2500米以下 | W43: 否 | X43: 10-35kV升压站（无主变） | Y43: 10-35kV升压站（含主变） | Z43: 66kV及以上升压站 | AA43: 220kV及以上升压站 | AB43: 全容量投运5年以内（含） | AC43: 全容量投运5年-10年（含） | AD43: 全容量投运10年-15年（含） | AE43: 全容量投运15年-20年（含） | AF43: 全容量投运20年以上
B44: 光伏电站 | C44: 100 | D44: 1 | E44: 0.95 | F44: 0.9 | G44: 0.85 | H44: 0.8 | I44: 0.75 | J44: 0.7 | K44: 1.1 | L44: 1 | M44: 0.9 | N44: 1 | O44: 1.05 | P44: 1 | Q44: 1.05 | R44: 1.1 | S44: 1 | T44: 1.1 | U44: 1.1 | V44: 1 | W44: 0.4 | X44: 0.6 | Y44: 0.75 | Z44: 1 | AA44: 1.1 | AB44: 0.8 | AC44: 0.9 | AD44: 1 | AE44: 1.1 | AF44: 1.2
C45: =IF(SUM(D45:AA45)=7,"正确","错误") -> #DIV/0! | D45: =IF(基本参数!$B$6<=10,1,0) -> 1 | E45: =IF(AND(基本参数!$B$6>10,基本参数!$B$6<=20),1,0) -> 0 | F45: =IF(AND(基本参数!$B$6>20,基本参数!$B$6<=40),1,0) -> 0 | G45: =IF(AND(基本参数!$B$6>40,基本参数!$B$6<=60),1,0) -> 0 | H45: =IF(AND(基本参数!$B$6>60,基本参数!$B$6<=80),1,0) -> 0 | I45: =IF(AND(基本参数!$B$6>80,基本参数!$B$6<=100),1,0) -> 0 | J45: =IF(基本参数!$B$6>100,1,0) -> 0 | K45: =IF(基本信息!$D$17=K43,1,0) -> 0 | L45: =IF(基本信息!$D$17=L43,1,0) -> 0 | M45: =IF(基本信息!$D$17=M43,1,0) -> 1 | N45: =IF(基本参数!$B$7/基本参数!$B$6<=1.05,1,0) -> #DIV/0! | O45: =IF(基本参数!$B$7/基本参数!$B$6>1.05,1,0) -> #DIV/0! | P45: =IF(基本信息!#REF!=P43,1,0) -> #REF! | Q45: =IF(基本信息!#REF!=Q43,1,0) -> #REF! | R45: =IF(基本信息!#REF!=R43,1,0) -> #REF! | S45: =Q10 -> #REF! | T45: =SUM(R10:T10) -> #REF! | U45: =IF(基本信息!$D$18=U43,1,0) -> 0 | V45: =IF(基本信息!$D$18=V43,1,0) -> 0 | W45: =IF(基本信息!$D$19=W43,1,0) -> 0 | X45: =IF(基本信息!$D$19=X43,1,0) -> 0 | Y45: =IF(基本信息!$D$19=Y43,1,0) -> 0 | Z45: =IF(基本信息!$D$19=Z43,1,0) -> 0 | AA45: =IF(基本信息!$D$19=AA43,1,0) -> 0
C46: XXMW委托运维1-5年 | D46: 6-10年 | E46: 11-15年 | F46: 16-20年 | G46: 20年以上
C47: =C44*SUMPRODUCT(D44:J44,D45:J45)*SUMPRODUCT(K44:M44,K45:M45)*SUMPRODUCT(N44:O44,N45:O45)*SUMPRODUCT(P44:R44,P45:R45)*SUMPRODUCT(S44:T44,S45:T45)*SUMPRODUCT(U44:V44,U45:V45)*SUMPRODUCT(W44:AA44,W45:AA45)*AB44 -> #DIV/0! | D47: =$C$47/$AB$44*AC44 -> #DIV/0! | E47: =$C$47/$AB$44*AD44 -> #DIV/0! | F47: =$C$47/$AB$44*AE44 -> #DIV/0! | G47: =$C$47/$AB$44*AF44 -> #DIV/0!
...

Sheet 电价电量取值表
A1: 各省光伏电价、弃电率参考值（标准1） | Q1: 各省光伏电价、弃电率参考值（标准2）
A2: 省份 | B2: 电价参考值 | I2: 弃电率参考值 | Q2: 省份 | R2: 电价参考值 | Y2: 弃电率参考值
B3: 2024年电价 | C3: 2025年预测电价 | D3: 2026年预测电价 | E3: 2027年预测电价 | F3: 2028年预测电价 | G3: 2029年预测电价 | H3: 2030年预测电价 | I3: 2024年弃电 | J3: 2025年预测弃电 | K3: 2026年预测弃电 | L3: 2027年预测弃电 | M3: 2028年预测弃电 | N3: 2029年预测弃电 | O3: 2030年预测弃电 | R3: 2024年电价 | S3: 2025年预测电价 | T3: 2026年预测电价 | U3: 2027年预测电价 | V3: 2028年预测电价 | W3: 2029年预测电价 | X3: 2030年预测电价 | Y3: 2024年弃电 | Z3: 2025年预测弃电 | AA3: 2026年预测弃电 | AB3: 2027年预测弃电 | AC3: 2028年预测弃电 | AD3: 2029年预测弃电 | AE3: 2030年预测弃电
A4: 北京 | B4: 0.3598 | C4: 0.3598 | D4: 0.3598 | E4: 0.3598 | F4: 0.3598 | G4: 0.3598 | H4: 0.3598 | I4: 0 | J4: 0.0067 | K4: 0.0133 | L4: 0.02 | M4: 0.0267 | N4: 0.0333 | O4: 0.04 | Q4: 北京 | R4: 0.3598 | S4: 0.3538 | T4: 0.3478 | U4: 0.3418 | V4: 0.3358 | W4: 0.3298 | X4: 0.3238 | Y4: 0 | Z4: 0.004 | AA4: 0.008 | AB4: 0.012 | AC4: 0.016 | AD4: 0.02 | AE4: 0.024
A5: 天津 | B5: 0.4175 | C5: 0.4088 | D5: 0.4002 | E5: 0.3915 | F5: 0.3828 | G5: 0.3742 | H5: 0.3655 | I5: 0.0174 | J5: 0.0195 | K5: 0.0216 | L5: 0.0237 | M5: 0.0258 | N5: 0.0279 | O5: 0.03 | Q5: 天津 | R5: 0.4175 | S5: 0.3967 | T5: 0.3758 | U5: 0.355 | V5: 0.3341 | W5: 0.3133 | X5: 0.2924 | Y5: 0.0174 | Z5: 0.0165 | AA5: 0.0156 | AB5: 0.0147 | AC5: 0.0138 | AD5: 0.0129 | AE5: 0.012
A6: 冀北 | B6: 0.3526 | C6: 0.3413 | D6: 0.33 | E6: 0.3187 | F6: 0.3074 | G6: 0.2961 | H6: 0.2848 | I6: 0.0681 | J6: 0.0901 | K6: 0.1121 | L6: 0.1341 | M6: 0.156 | N6: 0.178 | O6: 0.2 | Q6: 冀北 | R6: 0.3526 | S6: 0.3191 | T6: 0.2856 | U6: 0.2521 | V6: 0.2186 | W6: 0.1851 | X6: 0.1516 | Y6: 0.0681 | Z6: 0.0868 | AA6: 0.1054 | AB6: 0.1241 | AC6: 0.1427 | AD6: 0.1614 | AE6: 0.18
A7: 冀南 | B7: 0.3526 | C7: 0.3408 | D7: 0.329 | E7: 0.3172 | F7: 0.3054 | G7: 0.2936 | H7: 0.2818 | I7: 0.0681 | J7: 0.0901 | K7: 0.1121 | L7: 0.1341 | M7: 0.156 | N7: 0.178 | O7: 0.2 | Q7: 冀南 | R7: 0.3526 | S7: 0.3187 | T7: 0.2848 | U7: 0.251 | V7: 0.2171 | W7: 0.1832 | X7: 0.1493 | Y7: 0.0681 | Z7: 0.0868 | AA7: 0.1054 | AB7: 0.1241 | AC7: 0.1427 | AD7: 0.1614 | AE7: 0.18
A8: 山西 | B8: 0.2033 | C8: 0.207 | D8: 0.207 | E8: 0.207 | F8: 0.207 | G8: 0.207 | H8: 0.207 | I8: 0.0639 | J8: 0.0741 | K8: 0.0843 | L8: 0.0945 | M8: 0.1046 | N8: 0.1148 | O8: 0.125 | Q8: 山西 | R8: 0.2033 | S8: 0.2026 | T8: 0.2019 | U8: 0.2013 | V8: 0.2006 | W8: 0.1999 | X8: 0.1992 | Y8: 0.0639 | Z8: 0.0693 | AA8: 0.0746 | AB8: 0.08 | AC8: 0.0853 | AD8: 0.0907 | AE8: 0.096
A9: 蒙东 | B9: 0.265 | C9: 0.2579 | D9: 0.2508 | E9: 0.2437 | F9: 0.2366 | G9: 0.2295 | H9: 0.2224 | I9: 0.0509 | J9: 0.0658 | K9: 0.0806 | L9: 0.0955 | M9: 0.1103 | N9: 0.1252 | O9: 0.14 | Q9: 蒙东 | R9: 0.265 | S9: 0.2512 | T9: 0.2374 | U9: 0.2236 | V9: 0.2097 | W9: 0.1959 | X9: 0.1821 | Y9: 0.0509 | Z9: 0.0624 | AA9: 0.0739 | AB9: 0.0855 | AC9: 0.097 | AD9: 0.1085 | AE9: 0.12
A10: 蒙西 | B10: 0.2435 | C10: 0.2774 | D10: 0.2647 | E10: 0.2521 | F10: 0.2394 | G10: 0.2268 | H10: 0.2142 | I10: 0.0509 | J10: 0.0674 | K10: 0.0839 | L10: 0.1005 | M10: 0.117 | N10: 0.1335 | O10: 0.15 | Q10: 蒙西 | R10: 0.2435 | S10: 0.2277 | T10: 0.212 | U10: 0.1962 | V10: 0.1804 | W10: 0.1647 | X10: 0.1489 | Y10: 0.0509 | Z10: 0.0624 | AA10: 0.0739 | AB10: 0.0855 | AC10: 0.097 | AD10: 0.1085 | AE10: 0.12
A11: 辽宁 | B11: 0.4022 | C11: 0.3783 | D11: 0.3545 | E11: 0.3306 | F11: 0.3067 | G11: 0.2829 | H11: 0.259 | I11: 0.014 | J11: 0.0367 | K11: 0.0593 | L11: 0.082 | M11: 0.1047 | N11: 0.1273 | O11: 0.15 | Q11: 辽宁 | R11: 0.4022 | S11: 0.3677 | T11: 0.3331 | U11: 0.2986 | V11: 0.264 | W11: 0.2295 | X11: 0.1949 | Y11: 0.014 | Z11: 0.0357 | AA11: 0.0573 | AB11: 0.079 | AC11: 0.1007 | AD11: 0.1223 | AE11: 0.144
A12: 吉林 | B12: 0.3246 | C12: 0.3103 | D12: 0.2959 | E12: 0.2816 | F12: 0.2672 | G12: 0.2529 | H12: 0.2385 | I12: 0.0186 | J12: 0.0422 | K12: 0.0657 | L12: 0.0893 | M12: 0.1129 | N12: 0.1364 | O12: 0.16 | Q12: 吉林 | R12: 0.3246 | S12: 0.3036 | T12: 0.2826 | U12: 0.2616 | V12: 0.2406 | W12: 0.2196 | X12: 0.1986 | Y12: 0.0186 | Z12: 0.0395 | AA12: 0.0604 | AB12: 0.0813 | AC12: 0.1022 | AD12: 0.1231 | AE12: 0.144
A13: 黑龙江 | B13: 0.3422 | C13: 0.328 | D13: 0.3138 | E13: 0.2997 | F13: 0.2855 | G13: 0.2713 | H13: 0.2571 | I13: 0.0441 | J13: 0.0701 | K13: 0.0961 | L13: 0.1221 | M13: 0.148 | N13: 0.174 | O13: 0.2 | Q13: 黑龙江 | R13: 0.3422 | S13: 0.3124 | T13: 0.2825 | U13: 0.2527 | V13: 0.2229 | W13: 0.193 | X13: 0.1632 | Y13: 0.0441 | Z13: 0.0668 | AA13: 0.0894 | AB13: 0.1121 | AC13: 0.1347 | AD13: 0.1574 | AE13: 0.18
A14: 上海 | B14: 0.4736 | C14: 0.463 | D14: 0.4524 | E14: 0.4418 | F14: 0.4312 | G14: 0.4206 | H14: 0.41 | I14: 0.0003 | J14: 0.0003 | K14: 0.0002 | L14: 0.0002 | M14: 0.0001 | N14: 0.0001 | O14: 0 | Q14: 上海 | R14: 0.4736 | S14: 0.4501 | T14: 0.4265 | U14: 0.403 | V14: 0.3795 | W14: 0.3559 | X14: 0.3324 | Y14: 0.0003 | Z14: 0.0003 | AA14: 0.0002 | AB14: 0.0002 | AC14: 0.0001 | AD14: 0.0001 | AE14: 0
A15: 江苏 | B15: 0.4534 | C15: 0.4335 | D15: 0.4136 | E15: 0.3937 | F15: 0.3738 | G15: 0.3539 | H15: 0.334 | I15: 0.0041 | J15: 0.0134 | K15: 0.0227 | L15: 0.0321 | M15: 0.0414 | N15: 0.0507 | O15: 0.06 | Q15: 江苏 | R15: 0.4534 | S15: 0.4156 | T15: 0.3779 | U15: 0.3401 | V15: 0.3023 | W15: 0.2646 | X15: 0.2268 | Y15: 0.0041 | Z15: 0.0134 | AA15: 0.0227 | AB15: 0.0321 | AC15: 0.0414 | AD15: 0.0507 | AE15: 0.06
... A36: 新疆 | B36: 0.1681 | C36: 0.1681 | D36: 0.1681 | E36: 0.1681 | F36: 0.1681 | G36: 0.1681 | H36: 0.1681 | I36: 0.2222 | J36: 0.2218 | K36: 0.2215 | L36: 0.2211 | M36: 0.2207 | N36: 0.2204 | O36: 0.22 | Q36: 新疆 | R36: 0.1681 | S36: 0.1555 | T36: 0.1429 | U36: 0.1303 | V36: 0.1177 | W36: 0.1051 | X36: 0.0925 | Y36: 0.2222 | Z36: 0.2152 | AA36: 0.2081 | AB36: 0.2011 | AC36: 0.1941 | AD36: 0.187 | AE36: 0.18

Sheet 基本参数
A1: 年限和装机容量 | C1: 财务指标一览表
A2: 计算期（年） | B2: =B3+B4 -> 26 | C2: =财务指标一览表!B3 -> 投资回收期（税前） | E2: 年 | F2: =财务指标一览表!D3 -> #N/A | G2: =财务指标一览表!B11 -> 总投资收益率（ROI） | I2: % | J2: =财务指标一览表!D11 -> #VALUE! | K2: =财务指标一览表!B15 -> 盈亏平衡点（生产能力利用率） | M2: % | N2: =财务指标一览表!D15 -> #REF!
A3: 建设期（年） | B3: 1 | C3: =财务指标一览表!B4 -> 投资回收期（税后） | E3: 年 | F3: =财务指标一览表!D4 -> #N/A | G3: =财务指标一览表!B12 -> 投资利税率 | I3: % | J3: =财务指标一览表!D12 -> #VALUE! | K3: =财务指标一览表!B17 -> 度电投资 | M3: 元/kWh | N3: =财务指标一览表!D17 -> #DIV/0!
A4: 实际运行期（年） | B4: 25 | C4: =财务指标一览表!B5 -> 全投资内部收益率（税前） | E4: % | F4: =财务指标一览表!D5 -> #VALUE! | G4: =财务指标一览表!B13 -> 资本金净利润率（ROE） | I4: % | J4: =财务指标一览表!D13 -> #VALUE! | K4: =财务指标一览表!B18 -> 度电利润 | M4: 元/kWh | N4: =财务指标一览表!D18 -> #VALUE!
A5: 项目类型 | B5: 光伏 | C5: =财务指标一览表!B6 -> 全投资内部收益率（税后） | E5: % | F5: =财务指标一览表!D6 -> #VALUE! | G5: =财务指标一览表!B14 -> 资产负债率（最大值） | I5: % | J5: =财务指标一览表!D14 -> #DIV/0! | K5: =财务指标一览表!B19 -> 平准化度电成本（LCOE） | M5: 元/kWh | N5: =财务指标一览表!D19 -> #VALUE!
A6: 交流测装机容量（MW） | B6: =基本信息!D4 -> 0 | C6: =财务指标一览表!B7 -> 全投资净现值（税前） | E6: 万元 | F6: =财务指标一览表!D7 -> #VALUE! | G6: 年份 | J6: 第1年 | K6: 第2年 | L6: 第3年 | M6: 第4年 | N6: 第5年
A7: 直流侧装机容量（MWp） | B7: =基本信息!D5 -> 0 | C7: =财务指标一览表!B8 -> 全投资净现值（税后） | E7: 万元 | F7: =财务指标一览表!D8 -> #VALUE! | G7: 前五年利润总额 | I7: 万元 | J7: =财务指标一览表!D21 -> #VALUE! | K7: =财务指标一览表!E21 -> #VALUE! | L7: =财务指标一览表!F21 -> #VALUE! | M7: =财务指标一览表!G21 -> #VALUE! | N7: =财务指标一览表!H21 -> #VALUE!
A8: 运营期起始年 | B8: =基本信息!D3 -> 0 | C8: =财务指标一览表!B9 -> 资本金内部收益率 | E8: % | F8: =财务指标一览表!D9 -> #VALUE! | G8: 前五年EVA | I8: 万元 | J8: =财务指标一览表!D22 -> #VALUE! | K8: =财务指标一览表!E22 -> #VALUE! | L8: =财务指标一览表!F22 -> #VALUE! | M8: =财务指标一览表!G22 -> #VALUE! | N8: =财务指标一览表!H22 -> #VALUE!
A9: 第一年施工月数 | B9: 12 | C9: =财务指标一览表!B10 -> 资本金财务净现值 | E9: 万元 | F9: =财务指标一览表!D10 -> #VALUE! | G9: 前五年ROE | I9: % | J9: =财务指标一览表!D23 -> #VALUE! | K9: =财务指标一览表!E23 -> #VALUE! | L9: =财务指标一览表!F23 -> #VALUE! | M9: =财务指标一览表!G23 -> #VALUE! | N9: =财务指标一览表!H23 -> #VALUE!
A10: 最后一年施工月数 | B10: 12 | C10: 其他指标
A11: 建设期投资 | C11: 总投资（含流动资金） | E11: 万元 | F11: =投资计划与资金筹措表!C5 -> 0 | G11: 动态投资 | I11: 万元 | J11: =B12+B20 -> 0 | K11: 动态千瓦造价 | M11: 元/kWh | N11: =J11/B7*10 -> #DIV/0!
A12: 静态投资 | B12: =基本信息!D6 -> 0 | C12: 年均理论利用小时 | E12: h | F12: =收入和税金!C3*SUM(收入和税金!D5:AB5)/100/B4 -> 0 | G12: 弃电率（全寿期平均值） | I12: % | J12: =SUM(收入和税金!D7:AB7)/B4 -> #VALUE! | K12: 电价（全寿期平均值） | M12: 元/kWh | N12: =SUM(电价电量计算表!D13:AB13)/B4 -> #VALUE!
A13: 其中：无形资产（万元） | B13: 0
A14: 其中：其他资产（万元） | B14: 0
A15: 可抵扣税金（万元） | B15: =基本信息!D8 -> 0 | C15: 增值税部分
A16: 申请一次性留底退税 | B16: 否
A17: 资本金比例（%） | B17: 20
A18: 建设期利息计算方式 | B18: 手动输入
A19: 建设期利息（万元，手动输入） | B19: =基本信息!D7 -> 0
A20: 建设期利息（万元，最终） | B20: =IF(B18="自动计算",B12*(1-B17%)*B9*B36%/(24+B36%*B17%*B9),B19) -> 0
A21: 基准收益率
A22: 资本金基准收益率（%） | B22: 8
A23: 行业基准收益率（所得税前）（%） | B23: 8
A24: 行业基准收益率（所得税后）（%） | B24: 7
A25: 资本成本率（%） | B25: 3.29 | C25: wacc值，融资成本，借贷成本
A26: 流动资金
A27: 单位千瓦指标（元/kW） | B27: 30
A28: 自有流动资金比例（%） | B28: 100
A29: 流动资金贷款利率（%） | B29: =B31 -> 3
A30: 短期贷款
A31: 短期贷款利率（%） | B31: 3 | C31: 弥补亏损还长贷
A32: 长期借款
A33: 预定还款期（年） | B33: 15
A34: 运营期宽限（年） | B34: 0
A35: 还本付息方式 | B35: 等额还本利息照付
A36: 长期贷款利率（%） | B36: 3.5
A37: 年份 | B37: 第1年 | C37: 第2年 | D37: 第3年 | E37: 第4年 | F37: 第5年 | G37: 第6年 | H37: 第7年 | I37: 第8年 | J37: 第9年 | K37: 第10年 | L37: 第11年 | M37: 第12年 | N37: 第13年 | O37: 第14年 | P37: 第15年 | Q37: 第16年 | R37: 第17年 | S37: 第18年 | T37: 第19年 | U37: 第20年 | V37: 第21年 | W37: 第22年 | X37: 第23年 | Y37: 第24年 | Z37: 第25年 | AA37: 第26年
A38: 约定还款

Sheet 成本费用
A1: 折旧费
A2: 计算方式（选择） | C2: 年限折旧法
A3: 残值率 | B3: % | C3: 3
A4: 折旧年限 | B4: 年 | C4: 20
B5: 年份 | C5: 第1年 | D5: 第2年 | E5: 第3年 | F5: 第4年 | G5: 第5年 | H5: 第6年 | I5: 第7年 | J5: 第8年 | K5: 第9年 | L5: 第10年 | M5: 第11年 | N5: 第12年 | O5: 第13年 | P5: 第14年 | Q5: 第15年 | R5: 第16年 | S5: 第17年 | T5: 第18年 | U5: 第19年 | V5: 第20年 | W5: 第21年 | X5: 第22年 | Y5: 第23年 | Z5: 第24年 | AA5: 第25年 | AB5: 第26年
A6: 折旧费：年限折旧法 | B6: 万元 | D6: =$C89*(1-$C$3/100)/$C$4 -> 0 | E6: =$C89*(1-$C$3/100)/$C$4 -> 0 | F6: =$C89*(1-$C$3/100)/$C$4 -> 0 | G6: =$C89*(1-$C$3/100)/$C$4 -> 0 | H6: =$C89*(1-$C$3/100)/$C$4 -> 0 | I6: =$C89*(1-$C$3/100)/$C$4 -> 0 | J6: =$C89*(1-$C$3/100)/$C$4 -> 0 | K6: =$C89*(1-$C$3/100)/$C$4 -> 0 | ... W6: =$C89*(1-$C$3/100)/$C$4 -> 0 | X6: 0 | Y6: 0 | Z6: 0 | AA6: 0 | AB6: 0
A7: 折旧费：手动输入 | B7: 万元
A8: 最终折旧费 | B8: 万元 | D8: =IF($C$2="年限折旧法",D6,D7) -> 0 | E8: =IF($C$2="年限折旧法",E6,E7) -> 0 | F8: =IF($C$2="年限折旧法",F6,F7) -> 0 | G8: =IF($C$2="年限折旧法",G6,G7) -> 0 | H8: =IF($C$2="年限折旧法",H6,H7) -> 0 | I8: =IF($C$2="年限折旧法",I6,I7) -> 0 | J8: =IF($C$2="年限折旧法",J6,J7) -> 0 | K8: =IF($C$2="年限折旧法",K6,K7) -> 0 | ... AB8: =IF($C$2="年限折旧法",AB6,AB7) -> 0
A9: 维修费
A10: 计算方式（选择） | C10: 按比例
B11: 年份 | C11: 第1年 | D11: 第2年 | E11: 第3年 | F11: 第4年 | G11: 第5年 | H11: 第6年 | I11: 第7年 | J11: 第8年 | K11: 第9年 | L11: 第10年 | M11: 第11年 | N11: 第12年 | O11: 第13年 | P11: 第14年 | Q11: 第15年 | R11: 第16年 | S11: 第17年 | T11: 第18年 | U11: 第19年 | V11: 第20年 | W11: 第21年 | X11: 第22年 | Y11: 第23年 | Z11: 第24年 | AA11: 第25年 | AB11: 第26年
A12: 按费率 | B12: % | D12: 0 | E12: =D12 -> 0 | F12: =E12 -> 0 | G12: =F12 -> 0 | H12: =G12 -> 0 | I12: =H12 -> 0 | J12: =I12 -> 0 | K12: =J12 -> 0 | L12: =K12 -> 0 | ... AB12: =AA12 -> 0
B13: 万元 | D13: =$C$89*D12% -> 0 | E13: =$C$89*E12% -> 0 | F13: =$C$89*F12% -> 0 | G13: =$C$89*G12% -> 0 | H13: =$C$89*H12% -> 0 | I13: =$C$89*I12% -> 0 | J13: =$C$89*J12% -> 0 | K13: =$C$89*K12% -> 0 | ... AB13: =$C$89*AB12% -> 0
A14: 按比例 | B14: 元/kW | D14: =IF(COLUMN()-3<=成本费用取值表!$H$14,成本费用取值表!$C$18,成本费用取值表!$D$18)*IF(基本信息!#REF!="自主运维",1,0) -> #REF! | E14: =IF(COLUMN()-3<=成本费用取值表!$H$14,成本费用取值表!$C$18,成本费用取值表!$D$18)*IF(基本信息!#REF!="自主运维",1,0) -> #REF! | F14: =IF(COLUMN()-3<=成本费用取值表!$H$14,成本费用取值表!$C$18,成本费用取值表!$D$18)*IF(基本信息!#REF!="自主运维",1,0) -> #REF! | G14: =IF(COLUMN()-3<=成本费用取值表!$H$14,成本费用取值表!$C$18,成本费用取值表!$D$18)*IF(基本信息!#REF!="自主运维",1,0) -> #REF! | H14: =IF(COLUMN()-3<=成本费用取值表!$H$14,成本费用取值表!$C$18,成本费用取值表!$D$18)*IF(基本信息!#REF!="自主运维",1,0) -> #REF! | I14: =IF(COLUMN()-3<=成本费用取值表!$H$14,成本费用取值表!$C$18,成本费用取值表!$D$18)*IF(基本信息!#REF!="自主运维",1,0) -> #REF! | J14: =IF(COLUMN()-3<=成本费用取值表!$H$14,成本费用取值表!$C$18,成本费用取值表!$D$18)*IF(基本信息!#REF!="自主运维",1,0) -> #REF! | K14: =IF(COLUMN()-3<=成本费用取值表!$H$14,成本费用取值表!$C$18,成本费用取值表!$D$18)*IF(基本信息!#REF!="自主运维",1,0) -> #REF! | ... AB14: =IF(COLUMN()-3<=成本费用取值表!$H$14,成本费用取值表!$C$18,成本费用取值表!$D$18)*IF(基本信息!#REF!="自主运维",1,0) -> #REF!
B15: 万元 | D15: =D14*基本参数!$B7/10 -> #REF! | E15: =E14*基本参数!$B7/10 -> #REF! | F15: =F14*基本参数!$B7/10 -> #REF! | G15: =G14*基本参数!$B7/10 -> #REF! | H15: =H14*基本参数!$B7/10 -> #REF! | I15: =I14*基本参数!$B7/10 -> #REF! | J15: =J14*基本参数!$B7/10 -> #REF! | K15: =K14*基本参数!$B7/10 -> #REF! | ... AB15: =AB14*基本参数!$B7/10 -> #REF!
A16: 手动输入 | B16: 万元
A17: 最终维修费 | B17: 万元 | D17: =IF($C$10="按费率",D13,IF($C$10="按比例",D15,D16))*IF(OR(基本参数!$B$2<=COLUMN()-3,COLUMN()-3<基本参数!$B$3),0,1) -> #REF! | E17: =IF($C$10="按费率",E13,IF($C$10="按比例",E15,E16))*IF(OR(基本参数!$B$2<=COLUMN()-3,COLUMN()-3<基本参数!$B$3),0,1) -> #REF! | F17: =IF($C$10="按费率",F13,IF($C$10="按比例",F15,F16))*IF(OR(基本参数!$B$2<=COLUMN()-3,COLUMN()-3<基本参数!$B$3),0,1) -> #REF! | G17: =IF($C$10="按费率",G13,IF($C$10="按比例",G15,G16))*IF(OR(基本参数!$B$2<=COLUMN()-3,COLUMN()-3<基本参数!$B$3),0,1) -> #REF! | H17: =IF($C$10="按费率",H13,IF($C$10="按比例",H15,H16))*IF(OR(基本参数!$B$2<=COLUMN()-3,COLUMN()-3<基本参数!$B$3),0,1) -> #REF! | I17: =IF($C$10="按费率",I13,IF($C$10="按比例",I15,I16))*IF(OR(基本参数!$B$2<=COLUMN()-3,COLUMN()-3<基本参数!$B$3),0,1) -> #REF! | J17: =IF($C$10="按费率",J13,IF($C$10="按比例",J15,J16))*IF(OR(基本参数!$B$2<=COLUMN()-3,COLUMN()-3<基本参数!$B$3),0,1) -> #REF! | K17: =IF($C$10="按费率",K13,IF($C$10="按比例",K15,K16))*IF(OR(基本参数!$B$2<=COLUMN()-3,COLUMN()-3<基本参数!$B$3),0,1) -> #REF! | ... AB17: =IF($C$10="按费率",AB13,IF($C$10="按比例",AB15,AB16))*IF(OR(基本参数!$B$2<=COLUMN()-3,COLUMN()-3<基本参数!$B$3),0,1) -> #REF!
A18: 人工工资及福利
A19: 计算方式（选择） | C19: 自动计算
B20: 年份 | C20: 第1年 | D20: 第2年 | E20: 第3年 | F20: 第4年 | G20: 第5年 | H20: 第6年 | I20: 第7年 | J20: 第8年 | K20: 第9年 | L20: 第10年 | M20: 第11年 | N20: 第12年 | O20: 第13年 | P20: 第14年 | Q20: 第15年 | R20: 第16年 | S20: 第17年 | T20: 第18年 | U20: 第19年 | V20: 第20年 | W20: 第21年 | X20: 第22年 | Y20: 第23年 | Z20: 第24年 | AA20: 第25年 | AB20: 第26年
A21: 人员数量 | B21: 人 | D21: =成本费用取值表!C57 -> #REF! | E21: =D21 -> #REF! | F21: =E21 -> #REF! | G21: =F21 -> #REF! | H21: =G21 -> #REF! | I21: =H21 -> #REF! | J21: =I21 -> #REF! | K21: =J21 -> #REF! | L21: =K21 -> #REF! | ... AB21: =AA21 -> #REF!
A22: 人工年平均工资 | B22: 万元 | D22: =成本费用取值表!C53 -> 38.7 | E22: =D22 -> 38.7 | F22: =E22 -> 38.7 | G22: =F22 -> 38.7 | H22: =G22 -> 38.7 | I22: =H22 -> 38.7 | J22: =I22 -> 38.7 | K22: =J22 -> 38.7 | L22: =K22 -> 38.7 | ... AB22: =AA22 -> 38.7
A23: 福利费及其他 | B23: % | D23: 0 | E23: =D23 -> 0 | F23: =E23 -> 0 | G23: =F23 -> 0 | H23: =G23 -> 0 | I23: =H23 -> 0 | J23: =I23 -> 0 | K23: =J23 -> 0 | L23: =K23 -> 0 | ... AB23: =AA23 -> 0
A24: 手动输入 | B24: 万元
A25: 最终人工费 | B25: 万元 | D25: =IF($C$19="自动计算",D21*D22*(1+D23/100),D24)*IF(OR(基本参数!$B$2<=COLUMN()-3,COLUMN()-3<基本参数!$B$3),0,1) -> #REF! | E25: =IF($C$19="自动计算",E21*E22*(1+E23/100),E24)*IF(OR(基本参数!$B$2<=COLUMN()-3,COLUMN()-3<基本参数!$B$3),0,1) -> #REF! | F25: =IF($C$19="自动计算",F21*F22*(1+F23/100),F24)*IF(OR(基本参数!$B$2<=COLUMN()-3,COLUMN()-3<基本参数!$B$3),0,1) -> #REF! | G25: =IF($C$19="自动计算",G21*G22*(1+G23/100),G24)*IF(OR(基本参数!$B$2<=COLUMN()-3,COLUMN()-3<基本参数!$B$3),0,1) -> #REF! | H25: =IF($C$19="自动计算",H21*H22*(1+H23/100),H24)*IF(OR(基本参数!$B$2<=COLUMN()-3,COLUMN()-3<基本参数!$B$3),0,1) -> #REF! | I25: =IF($C$19="自动计算",I21*I22*(1+I23/100),I24)*IF(OR(基本参数!$B$2<=COLUMN()-3,COLUMN()-3<基本参数!$B$3),0,1) -> #REF! | J25: =IF($C$19="自动计算",J21*J22*(1+J23/100),J24)*IF(OR(基本参数!$B$2<=COLUMN()-3,COLUMN()-3<基本参数!$B$3),0,1) -> #REF! | K25: =IF($C$19="自动计算",K21*K22*(1+K23/100),K24)*IF(OR(基本参数!$B$2<=COLUMN()-3,COLUMN()-3<基本参数!$B$3),0,1) -> #REF! | ... AB25: =IF($C$19="自动计算",AB21*AB22*(1+AB23/100),AB24)*IF(OR(基本参数!$B$2<=COLUMN()-3,COLUMN()-3<基本参数!$B$3),0,1) -> #REF!
A26: 保险费
A27: 计算方式（选择） | C27: 按固定资产原值
A28: 费率 | B28: % | C28: =IF(成本费用取值表!T10=1,0.1246,0.0447) -> #REF!
B29: 年份 | C29: 第1年 | D29: 第2年 | E29: 第3年 | F29: 第4年 | G29: 第5年 | H29: 第6年 | I29: 第7年 | J29: 第8年 | K29: 第9年 | L29: 第10年 | M29: 第11年 | N29: 第12年 | O29: 第13年 | P29: 第14年 | Q29: 第15年 | R29: 第16年 | S29: 第17年 | T29: 第18年 | U29: 第19年 | V29: 第20年 | W29: 第21年 | X29: 第22年 | Y29: 第23年 | Z29: 第24年 | AA29: 第25年 | AB29: 第26年
A30: 按固定资产原值 | B30: 万元 | D30: =D89*$C$28/100 -> #REF! | E30: =E89*$C$28/100 -> #REF! | F30: =F89*$C$28/100 -> #REF! | G30: =G89*$C$28/100 -> #REF! | H30: =H89*$C$28/100 -> #REF! | I30: =I89*$C$28/100 -> #REF! | J30: =J89*$C$28/100 -> #REF! | K30: =K89*$C$28/100 -> #REF! | ... AB30: =AB89*$C$28/100 -> #REF!
A31: 按固定资产净值 | B31: 万元 | D31: =D90*$C$28/100 -> #REF! | E31: =E90*$C$28/100 -> #REF! | F31: =F90*$C$28/100 -> #REF! | G31: =G90*$C$28/100 -> #REF! | H31: =H90*$C$28/100 -> #REF! | I31: =I90*$C$28/100 -> #REF! | J31: =J90*$C$28/100 -> #REF! | K31: =K90*$C$28/100 -> #REF! | ... AB31: =AB90*$C$28/100 -> #REF!
A32: 手动输入 | B32: 万元
A33: 最终保险费 | B33: 万元 | D33: =IF($C$27="按固定资产原值",D30,IF($C$27="按固定资产净值",D31,D32))*IF(OR(基本参数!$B$2<=COLUMN()-3,COLUMN()-3<基本参数!$B$3),0,1) -> #REF! | E33: =IF($C$27="按固定资产原值",E30,IF($C$27="按固定资产净值",E31,E32))*IF(OR(基本参数!$B$2<=COLUMN()-3,COLUMN()-3<基本参数!$B$3),0,1) -> #REF! | F33: =IF($C$27="按固定资产原值",F30,IF($C$27="按固定资产净值",F31,F32))*IF(OR(基本参数!$B$2<=COLUMN()-3,COLUMN()-3<基本参数!$B$3),0,1) -> #REF! | G33: =IF($C$27="按固定资产原值",G30,IF($C$27="按固定资产净值",G31,G32))*IF(OR(基本参数!$B$2<=COLUMN()-3,COLUMN()-3<基本参数!$B$3),0,1) -> #REF! | H33: =IF($C$27="按固定资产原值",H30,IF($C$27="按固定资产净值",H31,H32))*IF(OR(基本参数!$B$2<=COLUMN()-3,COLUMN()-3<基本参数!$B$3),0,1) -> #REF! | I33: =IF($C$27="按固定资产原值",I30,IF($C$27="按固定资产净值",I31,I32))*IF(OR(基本参数!$B$2<=COLUMN()-3,COLUMN()-3<基本参数!$B$3),0,1) -> #REF! | J33: =IF($C$27="按固定资产原值",J30,IF($C$27="按固定资产净值",J31,J32))*IF(OR(基本参数!$B$2<=COLUMN()-3,COLUMN()-3<基本参数!$B$3),0,1) -> #REF! | K33: =IF($C$27="按固定资产原值",K30,IF($C$27="按固定资产净值",K31,K32))*IF(OR(基本参数!$B$2<=COLUMN()-3,COLUMN()-3<基本参数!$B$3),0,1) -> #REF! | ... AB33: =IF($C$27="按固定资产原值",AB30,IF($C$27="按固定资产净值",AB31,AB32))*IF(OR(基本参数!$B$2<=COLUMN()-3,COLUMN()-3<基本参数!$B$3),0,1) -> #REF!
A34: 材料费
A35: 计算方式（选择） | C35: 按比例
B36: 年份 | C36: 第1年 | D36: 第2年 | E36: 第3年 | F36: 第4年 | G36: 第5年 | H36: 第6年 | I36: 第7年 | J36: 第8年 | K36: 第9年 | L36: 第10年 | M36: 第11年 | N36: 第12年 | O36: 第13年 | P36: 第14年 | Q36: 第15年 | R36: 第16年 | S36: 第17年 | T36: 第18年 | U36: 第19年 | V36: 第20年 | W36: 第21年 | X36: 第22年 | Y36: 第23年 | Z36: 第24年 | AA36: 第25年 | AB36: 第26年
A37: 按比例 | B37: 元/kW | D37: =IF(COLUMN()-3<=成本费用取值表!$H$14,成本费用取值表!$C$28,成本费用取值表!$D$28)*IF(基本信息!#REF!="自主运维",1,0) -> #REF! | E37: =IF(COLUMN()-3<=成本费用取值表!$H$14,成本费用取值表!$C$28,成本费用取值表!$D$28)*IF(基本信息!#REF!="自主运维",1,0) -> #REF! | F37: =IF(COLUMN()-3<=成本费用取值表!$H$14,成本费用取值表!$C$28,成本费用取值表!$D$28)*IF(基本信息!#REF!="自主运维",1,0) -> #REF! | G37: =IF(COLUMN()-3<=成本费用取值表!$H$14,成本费用取值表!$C$28,成本费用取值表!$D$28)*IF(基本信息!#REF!="自主运维",1,0) -> #REF! | H37: =IF(COLUMN()-3<=成本费用取值表!$H$14,成本费用取值表!$C$28,成本费用取值表!$D$28)*IF(基本信息!#REF!="自主运维",1,0) -> #REF! | I37: =IF(COLUMN()-3<=成本费用取值表!$H$14,成本费用取值表!$C$28,成本费用取值表!$D$28)*IF(基本信息!#REF!="自主运维",1,0) -> #REF! | J37: =IF(COLUMN()-3<=成本费用取值表!$H$14,成本费用取值表!$C$28,成本费用取值表!$D$28)*IF(基本信息!#REF!="自主运维",1,0) -> #REF! | K37: =IF(COLUMN()-3<=成本费用取值表!$H$14,成本费用取值表!$C$28,成本费用取值表!$D$28)*IF(基本信息!#REF!="自主运维",1,0) -> #REF! | ... AB37: =IF(COLUMN()-3<=成本费用取值表!$H$14,成本费用取值表!$C$28,成本费用取值表!$D$28)*IF(基本信息!#REF!="自主运维",1,0) -> #REF!
B38: 万元 | D38: =D37*基本参数!$B$7/10 -> #REF! | E38: =E37*基本参数!$B$7/10 -> #REF! | F38: =F37*基本参数!$B$7/10 -> #REF! | G38: =G37*基本参数!$B$7/10 -> #REF! | H38: =H37*基本参数!$B$7/10 -> #REF! | I38: =I37*基本参数!$B$7/10 -> #REF! | J38: =J37*基本参数!$B$7/10 -> #REF! | K38: =K37*基本参数!$B$7/10 -> #REF! | ... AB38: =AB37*基本参数!$B$7/10 -> #REF!
A39: 手动输入 | B39: 万元
A40: 最终材料费 | B40: 万元 | D40: =IF($C$35="按比例",D38,D39)*IF(OR(基本参数!$B$2<=COLUMN()-3,COLUMN()-3<基本参数!$B$3),0,1) -> #REF! | E40: =IF($C$35="按比例",E38,E39)*IF(OR(基本参数!$B$2<=COLUMN()-3,COLUMN()-3<基本参数!$B$3),0,1) -> #REF! | F40: =IF($C$35="按比例",F38,F39)*IF(OR(基本参数!$B$2<=COLUMN()-3,COLUMN()-3<基本参数!$B$3),0,1) -> #REF! | G40: =IF($C$35="按比例",G38,G39)*IF(OR(基本参数!$B$2<=COLUMN()-3,COLUMN()-3<基本参数!$B$3),0,1) -> #REF! | H40: =IF($C$35="按比例",H38,H39)*IF(OR(基本参数!$B$2<=COLUMN()-3,COLUMN()-3<基本参数!$B$3),0,1) -> #REF! | I40: =IF($C$35="按比例",I38,I39)*IF(OR(基本参数!$B$2<=COLUMN()-3,COLUMN()-3<基本参数!$B$3),0,1) -> #REF! | J40: =IF($C$35="按比例",J38,J39)*IF(OR(基本参数!$B$2<=COLUMN()-3,COLUMN()-3<基本参数!$B$3),0,1) -> #REF! | K40: =IF($C$35="按比例",K38,K39)*IF(OR(基本参数!$B$2<=COLUMN()-3,COLUMN()-3<基本参数!$B$3),0,1) -> #REF! | ... AB40: =IF($C$35="按比例",AB38,AB39)*IF(OR(基本参数!$B$2<=COLUMN()-3,COLUMN()-3<基本参数!$B$3),0,1) -> #REF!
...

Sheet 收入和税金
A1: 发电量
A2: 发电量计算方式 | C2: 自动计算
A3: 首年无衰减无弃电利用小时 | B3: 小时 | C3: =基本信息!D9 -> 0
B4: 年份 | C4: 第1年 | D4: 第2年 | E4: 第3年 | F4: 第4年 | G4: 第5年 | H4: 第6年 | I4: 第7年 | J4: 第8年 | K4: 第9年 | L4: 第10年 | M4: 第11年 | N4: 第12年 | O4: 第13年 | P4: 第14年 | Q4: 第15年 | R4: 第16年 | S4: 第17年 | T4: 第18年 | U4: 第19年 | V4: 第20年 | W4: 第21年 | X4: 第22年 | Y4: 第23年 | Z4: 第24年 | AA4: 第25年 | AB4: 第26年
A5: 发电量系数计算方式 | C5: =基本信息!D10 -> 0 | D5: =IF($C$5="P型单玻",D64,IF($C$5="P型双玻",D65,IF($C$5="N型单玻",D66,IF($C$5="N型双玻",D67,IF($C$5="多晶单玻",D68,IF($C$5="多晶双玻",D69,D6))))))*IF(COLUMN()-2>基本参数!$B$2,0,1) -> 98 | E5: =IF($C$5="P型单玻",E64,IF($C$5="P型双玻",E65,IF($C$5="N型单玻",E66,IF($C$5="N型双玻",E67,IF($C$5="多晶单玻",E68,IF($C$5="多晶双玻",E69,E6))))))*IF(COLUMN()-2>基本参数!$B$2,0,1) -> 97.45 | F5: =IF($C$5="P型单玻",F64,IF($C$5="P型双玻",F65,IF($C$5="N型单玻",F66,IF($C$5="N型双玻",F67,IF($C$5="多晶单玻",F68,IF($C$5="多晶双玻",F69,F6))))))*IF(COLUMN()-2>基本参数!$B$2,0,1) -> 96.9 | G5: =IF($C$5="P型单玻",G64,IF($C$5="P型双玻",G65,IF($C$5="N型单玻",G66,IF($C$5="N型双玻",G67,IF($C$5="多晶单玻",G68,IF($C$5="多晶双玻",G69,G6))))))*IF(COLUMN()-2>基本参数!$B$2,0,1) -> 96.35 | H5: =IF($C$5="P型单玻",H64,IF($C$5="P型双玻",H65,IF($C$5="N型单玻",H66,IF($C$5="N型双玻",H67,IF($C$5="多晶单玻",H68,IF($C$5="多晶双玻",H69,H6))))))*IF(COLUMN()-2>基本参数!$B$2,0,1) -> 95.8 | I5: =IF($C$5="P型单玻",I64,IF($C$5="P型双玻",I65,IF($C$5="N型单玻",I66,IF($C$5="N型双玻",I67,IF($C$5="多晶单玻",I68,IF($C$5="多晶双玻",I69,I6))))))*IF(COLUMN()-2>基本参数!$B$2,0,1) -> 95.25 | J5: =IF($C$5="P型单玻",J64,IF($C$5="P型双玻",J65,IF($C$5="N型单玻",J66,IF($C$5="N型双玻",J67,IF($C$5="多晶单玻",J68,IF($C$5="多晶双玻",J69,J6))))))*IF(COLUMN()-2>基本参数!$B$2,0,1) -> 94.7 | K5: =IF($C$5="P型单玻",K64,IF($C$5="P型双玻",K65,IF($C$5="N型单玻",K66,IF($C$5="N型双玻",K67,IF($C$5="多晶单玻",K68,IF($C$5="多晶双玻",K69,K6))))))*IF(COLUMN()-2>基本参数!$B$2,0,1) -> 94.15 | ... AB5: =IF($C$5="P型单玻",AB64,IF($C$5="P型双玻",AB65,IF($C$5="N型单玻",AB66,IF($C$5="N型双玻",AB67,IF($C$5="多晶单玻",AB68,IF($C$5="多晶双玻",AB69,AB6))))))*IF(COLUMN()-2>基本参数!$B$2,0,1) -> 84.8
A6: 手动输入发电量系数 | B6: % | D6: 98 | E6: 97.45 | F6: 96.9 | G6: 96.35 | H6: 95.8 | I6: 95.25 | J6: 94.7 | K6: 94.15 | L6: 93.6 | M6: 93.05 | N6: 92.5 | O6: 91.95 | P6: 91.4 | Q6: 90.85 | R6: 90.3 | S6: 89.75 | T6: 89.2 | U6: 88.65 | V6: 88.1 | W6: 87.55 | X6: 87 | Y6: 86.45 | Z6: 85.9 | AA6: 85.35 | AB6: 84.8
A7: 弃电率计算方式 | C7: =基本信息!D12 -> 0 | D7: =IF($C$7="手动输入",D8,VLOOKUP(地区辅助页!$E$1,IF($C$7="标准1",电价电量取值表!$A:$O,电价电量取值表!$Q:$AE),IF(电价电量计算表!D15>2030,15,电价电量计算表!D15-2025+10),FALSE))*IF(COLUMN()-2>基本参数!$B$2,0,100) -> #VALUE! | E7: =IF($C$7="手动输入",E8,VLOOKUP(地区辅助页!$E$1,IF($C$7="标准1",电价电量取值表!$A:$O,电价电量取值表!$Q:$AE),IF(电价电量计算表!E15>2030,15,电价电量计算表!E15-2025+10),FALSE))*IF(COLUMN()-2>基本参数!$B$2,0,100) -> #VALUE! | F7: =IF($C$7="手动输入",F8,VLOOKUP(地区辅助页!$E$1,IF($C$7="标准1",电价电量取值表!$A:$O,电价电量取值表!$Q:$AE),IF(电价电量计算表!F15>2030,15,电价电量计算表!F15-2025+10),FALSE))*IF(COLUMN()-2>基本参数!$B$2,0,100) -> #VALUE! | G7: =IF($C$7="手动输入",G8,VLOOKUP(地区辅助页!$E$1,IF($C$7="标准1",电价电量取值表!$A:$O,电价电量取值表!$Q:$AE),IF(电价电量计算表!G15>2030,15,电价电量计算表!G15-2025+10),FALSE))*IF(COLUMN()-2>基本参数!$B$2,0,100) -> #VALUE! | H7: =IF($C$7="手动输入",H8,VLOOKUP(地区辅助页!$E$1,IF($C$7="标准1",电价电量取值表!$A:$O,电价电量取值表!$Q:$AE),IF(电价电量计算表!H15>2030,15,电价电量计算表!H15-2025+10),FALSE))*IF(COLUMN()-2>基本参数!$B$2,0,100) -> #VALUE! | I7: =IF($C$7="手动输入",I8,VLOOKUP(地区辅助页!$E$1,IF($C$7="标准1",电价电量取值表!$A:$O,电价电量取值表!$Q:$AE),IF(电价电量计算表!I15>2030,15,电价电量计算表!I15-2025+10),FALSE))*IF(COLUMN()-2>基本参数!$B$2,0,100) -> #VALUE! | J7: =IF($C$7="手动输入",J8,VLOOKUP(地区辅助页!$E$1,IF($C$7="标准1",电价电量取值表!$A:$O,电价电量取值表!$Q:$AE),IF(电价电量计算表!J15>2030,15,电价电量计算表!J15-2025+10),FALSE))*IF(COLUMN()-2>基本参数!$B$2,0,100) -> #VALUE! | K7: =IF($C$7="手动输入",K8,VLOOKUP(地区辅助页!$E$1,IF($C$7="标准1",电价电量取值表!$A:$O,电价电量取值表!$Q:$AE),IF(电价电量计算表!K15>2030,15,电价电量计算表!K15-2025+10),FALSE))*IF(COLUMN()-2>基本参数!$B$2,0,100) -> #VALUE! | ... AB7: =IF($C$7="手动输入",AB8,VLOOKUP(地区辅助页!$E$1,IF($C$7="标准1",电价电量取值表!$A:$O,电价电量取值表!$Q:$AE),IF(电价电量计算表!AB15>2030,15,电价电量计算表!AB15-2025+10),FALSE))*IF(COLUMN()-2>基本参数!$B$2,0,100) -> #VALUE!
A8: 手动输入弃电率 | B8: %
A9: 手动输入上网电量 | B9: MWh | D9: 0 | E9: =D9 -> 0 | F9: =E9 -> 0 | G9: =F9 -> 0 | H9: =G9 -> 0 | I9: =H9 -> 0 | J9: =I9 -> 0 | K9: =J9 -> 0 | L9: =K9 -> 0 | ... AB9: =AA9 -> 0
A10: 最终上网电量 | B10: MWh | D10: =IF($C$2="手动输入",D9,$C$3*IF($C$5="手动输入",D6,D5)/100*IF($C$7="手动输入",100-D8,100-D7)/100*基本参数!$B$7) -> #VALUE! | E10: =IF($C$2="手动输入",E9,$C$3*IF($C$5="手动输入",E6,E5)/100*IF($C$7="手动输入",100-E8,100-E7)/100*基本参数!$B$7) -> #VALUE! | F10: =IF($C$2="手动输入",F9,$C$3*IF($C$5="手动输入",F6,F5)/100*IF($C$7="手动输入",100-F8,100-F7)/100*基本参数!$B$7) -> #VALUE! | G10: =IF($C$2="手动输入",G9,$C$3*IF($C$5="手动输入",G6,G5)/100*IF($C$7="手动输入",100-G8,100-G7)/100*基本参数!$B$7) -> #VALUE! | H10: =IF($C$2="手动输入",H9,$C$3*IF($C$5="手动输入",H6,H5)/100*IF($C$7="手动输入",100-H8,100-H7)/100*基本参数!$B$7) -> #VALUE! | I10: =IF($C$2="手动输入",I9,$C$3*IF($C$5="手动输入",I6,I5)/100*IF($C$7="手动输入",100-I8,100-I7)/100*基本参数!$B$7) -> #VALUE! | J10: =IF($C$2="手动输入",J9,$C$3*IF($C$5="手动输入",J6,J5)/100*IF($C$7="手动输入",100-J8,100-J7)/100*基本参数!$B$7) -> #VALUE! | K10: =IF($C$2="手动输入",K9,$C$3*IF($C$5="手动输入",K6,K5)/100*IF($C$7="手动输入",100-K8,100-K7)/100*基本参数!$B$7) -> #VALUE! | ... AB10: =IF($C$2="手动输入",AB9,$C$3*IF($C$5="手动输入",AB6,AB5)/100*IF($C$7="手动输入",100-AB8,100-AB7)/100*基本参数!$B$7) -> #VALUE!
A11: 应付利润比例
A12: 应付利润比例 | B12: % | C12: 100
A13: 增值税
A14: 增值税政策 | B14: 即征即退50% | C14: 否
B15: 年份 | C15: 第1年 | D15: 第2年 | E15: 第3年 | F15: 第4年 | G15: 第5年 | H15: 第6年 | I15: 第7年 | J15: 第8年 | K15: 第9年 | L15: 第10年 | M15: 第11年 | N15: 第12年 | O15: 第13年 | P15: 第14年 | Q15: 第15年 | R15: 第16年 | S15: 第17年 | T15: 第18年 | U15: 第19年 | V15: 第20年 | W15: 第21年 | X15: 第22年 | Y15: 第23年 | Z15: 第24年 | AA15: 第25年 | AB15: 第26年
A16: 最终税率 | B16: % | D16: 13 | E16: =D16 -> 13 | F16: =E16 -> 13 | G16: =F16 -> 13 | H16: =G16 -> 13 | I16: =H16 -> 13 | J16: =I16 -> 13 | K16: =J16 -> 13 | L16: =K16 -> 13 | ... AB16: =AA16 -> 13
A17: 企业所得税
A18: 计算方式（选择） | C18: 自动计算
A19: 企业所得税政策 | B19: 西部大开发 | C19: =IF(_xlfn.XLOOKUP(基本信息!D11,地区辅助页!B:B,地区辅助页!A:A,"",0)>20,"是","否") -> 否
B20: 年份 | C20: 第1年 | D20: 第2年 | E20: 第3年 | F20: 第4年 | G20: 第5年 | H20: 第6年 | I20: 第7年 | J20: 第8年 | K20: 第9年 | L20: 第10年 | M20: 第11年 | N20: 第12年 | O20: 第13年 | P20: 第14年 | Q20: 第15年 | R20: 第16年 | S20: 第17年 | T20: 第18年 | U20: 第19年 | V20: 第20年 | W20: 第21年 | X20: 第22年 | Y20: 第23年 | Z20: 第24年 | AA20: 第25年 | AB20: 第26年
A21: 自动计算 | B21: % | D21: =IF($C$19="是",IF(基本参数!$B$8+COLUMN()-3<=2030,15,25),25)*0 -> 0 | E21: =IF($C$19="是",IF(基本参数!$B$8+COLUMN()-3<=2030,15,25),25)*0 -> 0 | F21: =IF($C$19="是",IF(基本参数!$B$8+COLUMN()-3<=2030,15,25),25)*0 -> 0 | G21: =IF($C$19="是",IF(基本参数!$B$8+COLUMN()-3<=2030,15,25),25)*0.5 -> 12.5 | H21: =IF($C$19="是",IF(基本参数!$B$8+COLUMN()-3<=2030,15,25),25)*0.5 -> 12.5 | I21: =IF($C$19="是",IF(基本参数!$B$8+COLUMN()-3<=2030,15,25),25)*0.5 -> 12.5 | J21: =IF($C$19="是",IF(基本参数!$B$8+COLUMN()-3<=2030,15,25),25) -> 25 | K21: =IF($C$19="是",IF(基本参数!$B$8+COLUMN()-3<=2030,15,25),25) -> 25 | L21: =IF($C$19="是",IF(基本参数!$B$8+COLUMN()-3<=2030,15,25),25) -> 25 | M21: =IF($C$19="是",IF(基本参数!$B$8+COLUMN()-3<=2030,15,25),25) -> 25 | N21: =IF($C$19="是",IF(基本参数!$B$8+COLUMN()-3<=2030,15,25),25) -> 25 | O21: =IF($C$19="是",IF(基本参数!$B$8+COLUMN()-3<=2030,15,25),25) -> 25 | P21: =IF($C$19="是",IF(基本参数!$B$8+COLUMN()-3<=2030,15,25),25) -> 25 | Q21: =IF($C$19="是",IF(基本参数!$B$8+COLUMN()-3<=2030,15,25),25) -> 25 | ... AB21: =IF($C$19="是",IF(基本参数!$B$8+COLUMN()-3<=2030,15,25),25) -> 25
A22: 手动输入 | B22: % | D22: 0 | E22: 0 | F22: 0 | G22: 12.5 | H22: 12.5 | I22: 12.5 | J22: 25 | K22: 25 | L22: 25 | M22: 25 | N22: 25 | O22: 25 | P22: 25 | Q22: 25 | R22: 25 | S22: 25 | T22: 25 | U22: 25 | V22: 25 | W22: 25 | X22: 25 | Y22: 25 | Z22: 25 | AA22: 25 | AB22: 25
A23: 最终税率 | B23: % | D23: =IF($C$18="自动计算",D21,D22) -> 0 | E23: =IF($C$18="自动计算",E21,E22) -> 0 | F23: =IF($C$18="自动计算",F21,F22) -> 0 | G23: =IF($C$18="自动计算",G21,G22) -> 12.5 | H23: =IF($C$18="自动计算",H21,H22) -> 12.5 | I23: =IF($C$18="自动计算",I21,I22) -> 12.5 | J23: =IF($C$18="自动计算",J21,J22) -> 25 | K23: =IF($C$18="自动计算",K21,K22) -> 25 | ... AB23: =IF($C$18="自动计算",AB21,AB22) -> 25
A24: 城市维护建设税
B25: 年份 | C25: 第1年 | D25: 第2年 | E25: 第3年 | F25: 第4年 | G25: 第5年 | H25: 第6年 | I25: 第7年 | J25: 第8年 | K25: 第9年 | L25: 第10年 | M25: 第11年 | N25: 第12年 | O25: 第13年 | P25: 第14年 | Q25: 第15年 | R25: 第16年 | S25: 第17年 | T25: 第18年 | U25: 第19年 | V25: 第20年 | W25: 第21年 | X25: 第22年 | Y25: 第23年 | Z25: 第24年 | AA25: 第25年 | AB25: 第26年
A26: 最终税率 | B26: % | D26: 5 | E26: =D26 -> 5 | F26: =E26 -> 5 | G26: =F26 -> 5 | H26: =G26 -> 5 | I26: =H26 -> 5 | J26: =I26 -> 5 | K26: =J26 -> 5 | L26: =K26 -> 5 | ... AB26: =AA26 -> 5
A27: 教育费附加
B28: 年份 | C28: 第1年 | D28: 第2年 | E28: 第3年 | F28: 第4年 | G28: 第5年 | H28: 第6年 | I28: 第7年 | J28: 第8年 | K28: 第9年 | L28: 第10年 | M28: 第11年 | N28: 第12年 | O28: 第13年 | P28: 第14年 | Q28: 第15年 | R28: 第16年 | S28: 第17年 | T28: 第18年 | U28: 第19年 | V28: 第20年 | W28: 第21年 | X28: 第22年 | Y28: 第23年 | Z28: 第24年 | AA28: 第25年 | AB28: 第26年
A29: 最终税率 | B29: % | D29: 5 | E29: =D29 -> 5 | F29: =E29 -> 5 | G29: =F29 -> 5 | H29: =G29 -> 5 | I29: =H29 -> 5 | J29: =I29 -> 5 | K29: =J29 -> 5 | L29: =K29 -> 5 | ... AB29: =AA29 -> 5
A30: 法定盈余公积金比例
B31: 年份 | C31: 第1年 | D31: 第2年 | E31: 第3年 | F31: 第4年 | G31: 第5年 | H31: 第6年 | I31: 第7年 | J31: 第8年 | K31: 第9年 | L31: 第10年 | M31: 第11年 | N31: 第12年 | O31: 第13年 | P31: 第14年 | Q31: 第15年 | R31: 第16年 | S31: 第17年 | T31: 第18年 | U31: 第19年 | V31: 第20年 | W31: 第21年 | X31: 第22年 | Y31: 第23年 | Z31: 第24年 | AA31: 第25年 | AB31: 第26年
A32: 最终比例 | B32: % | D32: 10 | E32: =D32 -> 10 | F32: =E32 -> 10 | G32: =F32 -> 10 | H32: =G32 -> 10 | I32: =H32 -> 10 | J32: =I32 -> 10 | K32: =J32 -> 10 | L32: =K32 -> 10 | ... AB32: =AA32 -> 10
A33: 任意盈余公积金比例
B34: 年份 | C34: 第1年 | D34: 第2年 | E34: 第3年 | F34: 第4年 | G34: 第5年 | H34: 第6年 | I34: 第7年 | J34: 第8年 | K34: 第9年 | L34: 第10年 | M34: 第11年 | N34: 第12年 | O34: 第13年 | P34: 第14年 | Q34: 第15年 | R34: 第16年 | S34: 第17年 | T34: 第18年 | U34: 第19年 | V34: 第20年 | W34: 第21年 | X34: 第22年 | Y34: 第23年 | Z34: 第24年 | AA34: 第25年 | AB34: 第26年
A35: 最终比例 | B35: % | D35: 0 | E35: =D35 -> 0 | F35: =E35 -> 0 | G35: =F35 -> 0 | H35: =G35 -> 0 | I35: =H35 -> 0 | J35: =I35 -> 0 | K35: =J35 -> 0 | L35: =K35 -> 0 | ... AB35: =AA35 -> 0
A36: 其他收入（应交所得税）
B37: 年份 | C37: 第1年 | D37: 第2年 | E37: 第3年 | F37: 第4年 | G37: 第5年 | H37: 第6年 | I37: 第7年 | J37: 第8年 | K37: 第9年 | L37: 第10年 | M37: 第11年 | N37: 第12年 | O37: 第13年 | P37: 第14年 | Q37: 第15年 | R37: 第16年 | S37: 第17年 | T37: 第18年 | U37: 第19年 | V37: 第20年 | W37: 第21年 | X37: 第22年 | Y37: 第23年 | Z37: 第24年 | AA37: 第25年 | AB37: 第26年
A38: 一次性留抵退税 | B38: 万元 | D38: =IF(基本参数!$B$16="是",IF(COLUMN()-2=基本参数!$B$3+1,SUM(基本参数!$B$15:$B$15),0),0) -> 0 | E38: =IF(基本参数!$B$16="是",IF(COLUMN()-2=基本参数!$B$3+1,SUM(基本参数!$B$15:$B$15),0),0) -> 0 | F38: =IF(基本参数!$B$16="是",IF(COLUMN()-2=基本参数!$B$3+1,SUM(基本参数!$B$15:$B$15),0),0) -> 0 | G38: =IF(基本参数!$B$16="是",IF(COLUMN()-2=基本参数!$B$3+1,SUM(基本参数!$B$15:$B$15),0),0) -> 0 | H38: =IF(基本参数!$B$16="是",IF(COLUMN()-2=基本参数!$B$3+1,SUM(基本参数!$B$15:$B$15),0),0) -> 0 | I38: =IF(基本参数!$B$16="是",IF(COLUMN()-2=基本参数!$B$3+1,SUM(基本参数!$B$15:$B$15),0),0) -> 0 | J38: =IF(基本参数!$B$16="是",IF(COLUMN()-2=基本参数!$B$3+1,SUM(基本参数!$B$15:$B$15),0),0) -> 0 | K38: =IF(基本参数!$B$16="是",IF(COLUMN()-2=基本参数!$B$3+1,SUM(基本参数!$B$15:$B$15),0),0) -> 0 | ... AB38: =IF(基本参数!$B$16="是",IF(COLUMN()-2=基本参数!$B$3+1,SUM(基本参数!$B$15:$B$15),0),0) -> 0
A39: 增值税率 | B39: % | C39: 0
A40: 收入2金额 | B40: 万元 | D40: 0 | E40: =D40 -> 0 | F40: =E40 -> 0 | G40: =F40 -> 0 | H40: =G40 -> 0 | I40: =H40 -> 0 | J40: =I40 -> 0 | K40: =J40 -> 0 | L40: =K40 -> 0 | ... AB40: =AA40 -> 0
...

Sheet 电价电量计算表
A1: 电价
A2: 电价取值标准 | B2: 标准1
A3: 手动输入电价算法 | B3: 综合电价
B4: 年份 | C4: 第1年 | D4: 第2年 | E4: 第3年 | F4: 第4年 | G4: 第5年 | H4: 第6年 | I4: 第7年 | J4: 第8年 | K4: 第9年 | L4: 第10年 | M4: 第11年 | N4: 第12年 | O4: 第13年 | P4: 第14年 | Q4: 第15年 | R4: 第16年 | S4: 第17年 | T4: 第18年 | U4: 第19年 | V4: 第20年 | W4: 第21年 | X4: 第22年 | Y4: 第23年 | Z4: 第24年 | AA4: 第25年 | AB4: 第26年
A5: 综合结算电价（直接手动输入） | B5: 元/kWh | D5: 0.3 | E5: 0.3 | F5: 0.3 | G5: 0.3 | H5: 0.3 | I5: 0.3 | J5: 0.3 | K5: 0.3 | L5: 0.3 | M5: 0.3 | N5: 0.3 | O5: 0.3 | P5: 0.3 | Q5: 0.3 | R5: 0.3 | S5: 0.3 | T5: 0.3 | U5: 0.3 | V5: 0.3 | W5: 0.3 | X5: 0.3 | Y5: 0.3 | Z5: 0.3 | AA5: 0.3 | AB5: 0.3
A6: 分项电价1 | B6: 元/kWh | D6: 0.4 | E6: 0.4 | F6: 0.4 | G6: 0.4 | H6: 0.4 | I6: 0.4 | J6: 0.4 | K6: 0.4 | L6: 0.4 | M6: 0.4 | N6: 0.4 | O6: 0.4 | P6: 0.4 | Q6: 0.4 | R6: 0.4 | S6: 0.4 | T6: 0.4 | U6: 0.4 | V6: 0.4 | W6: 0.4 | X6: 0.4 | Y6: 0.4 | Z6: 0.4 | AA6: 0.4 | AB6: 0.4
B7: 占比（%） | D7: 100 | E7: 100 | F7: 100 | G7: 100 | H7: 100 | I7: 100 | J7: 100 | K7: 100 | L7: 100 | M7: 100 | N7: 100 | O7: 100 | P7: 100 | Q7: 100 | R7: 100 | S7: 100 | T7: 100 | U7: 100 | V7: 100 | W7: 100 | X7: 100 | Y7: 100 | Z7: 100 | AA7: 100 | AB7: 100
A8: 分项电价2 | B8: 元/kWh
B9: 占比（%）
A10: 分项电价3 | B10: 元/kWh
B11: 占比（%）
A12: 综合结算电价（根据分项加权平均） | B12: 元/kWh | D12: =D6*IF($B$7="占比（%）",D7%,D7/D14)+D8*IF($B$9="占比（%）",D9%,D9/D14)+D10*IF($B$11="占比（%）",D11%,D11/D14) -> 0.4 | E12: =E6*IF($B$7="占比（%）",E7%,E7/E14)+E8*IF($B$9="占比（%）",E9%,E9/E14)+E10*IF($B$11="占比（%）",E11%,E11/E14) -> 0.4 | F12: =F6*IF($B$7="占比（%）",F7%,F7/F14)+F8*IF($B$9="占比（%）",F9%,F9/F14)+F10*IF($B$11="占比（%）",F11%,F11/F14) -> 0.4 | G12: =G6*IF($B$7="占比（%）",G7%,G7/G14)+G8*IF($B$9="占比（%）",G9%,G9/G14)+G10*IF($B$11="占比（%）",G11%,G11/G14) -> 0.4 | H12: =H6*IF($B$7="占比（%）",H7%,H7/H14)+H8*IF($B$9="占比（%）",H9%,H9/H14)+H10*IF($B$11="占比（%）",H11%,H11/H14) -> 0.4 | I12: =I6*IF($B$7="占比（%）",I7%,I7/I14)+I8*IF($B$9="占比（%）",I9%,I9/I14)+I10*IF($B$11="占比（%）",I11%,I11/I14) -> 0.4 | J12: =J6*IF($B$7="占比（%）",J7%,J7/J14)+J8*IF($B$9="占比（%）",J9%,J9/J14)+J10*IF($B$11="占比（%）",J11%,J11/J14) -> 0.4 | K12: =K6*IF($B$7="占比（%）",K7%,K7/K14)+K8*IF($B$9="占比（%）",K9%,K9/K14)+K10*IF($B$11="占比（%）",K11%,K11/K14) -> 0.4 | ... AB12: =AB6*IF($B$7="占比（%）",AB7%,AB7/AB14)+AB8*IF($B$9="占比（%）",AB9%,AB9/AB14)+AB10*IF($B$11="占比（%）",AB11%,AB11/AB14) -> 0.4
A13: 综合结算电价（最终） | B13: 元/kWh | D13: =IF($B$2="手动输入",IF($B$3="综合电价",D5,D12),VLOOKUP(地区辅助页!$E$1,IF($B$2="标准1",电价电量取值表!$A:$H,电价电量取值表!$Q:$X),IF(D15>2030,8,D15-2025+3),FALSE))*IF(OR(基本参数!$B$2<=COLUMN()-3,COLUMN()-3<基本参数!$B$3),0,1) -> #VALUE! | E13: =IF($B$2="手动输入",IF($B$3="综合电价",E5,E12),VLOOKUP(地区辅助页!$E$1,IF($B$2="标准1",电价电量取值表!$A:$H,电价电量取值表!$Q:$X),IF(E15>2030,8,E15-2025+3),FALSE))*IF(OR(基本参数!$B$2<=COLUMN()-3,COLUMN()-3<基本参数!$B$3),0,1) -> #VALUE! | F13: =IF($B$2="手动输入",IF($B$3="综合电价",F5,F12),VLOOKUP(地区辅助页!$E$1,IF($B$2="标准1",电价电量取值表!$A:$H,电价电量取值表!$Q:$X),IF(F15>2030,8,F15-2025+3),FALSE))*IF(OR(基本参数!$B$2<=COLUMN()-3,COLUMN()-3<基本参数!$B$3),0,1) -> #VALUE! | G13: =IF($B$2="手动输入",IF($B$3="综合电价",G5,G12),VLOOKUP(地区辅助页!$E$1,IF($B$2="标准1",电价电量取值表!$A:$H,电价电量取值表!$Q:$X),IF(G15>2030,8,G15-2025+3),FALSE))*IF(OR(基本参数!$B$2<=COLUMN()-3,COLUMN()-3<基本参数!$B$3),0,1) -> #VALUE! | H13: =IF($B$2="手动输入",IF($B$3="综合电价",H5,H12),VLOOKUP(地区辅助页!$E$1,IF($B$2="标准1",电价电量取值表!$A:$H,电价电量取值表!$Q:$X),IF(H15>2030,8,H15-2025+3),FALSE))*IF(OR(基本参数!$B$2<=COLUMN()-3,COLUMN()-3<基本参数!$B$3),0,1) -> #VALUE! | I13: =IF($B$2="手动输入",IF($B$3="综合电价",I5,I12),VLOOKUP(地区辅助页!$E$1,IF($B$2="标准1",电价电量取值表!$A:$H,电价电量取值表!$Q:$X),IF(I15>2030,8,I15-2025+3),FALSE))*IF(OR(基本参数!$B$2<=COLUMN()-3,COLUMN()-3<基本参数!$B$3),0,1) -> #VALUE! | J13: =IF($B$2="手动输入",IF($B$3="综合电价",J5,J12),VLOOKUP(地区辅助页!$E$1,IF($B$2="标准1",电价电量取值表!$A:$H,电价电量取值表!$Q:$X),IF(J15>2030,8,J15-2025+3),FALSE))*IF(OR(基本参数!$B$2<=COLUMN()-3,COLUMN()-3<基本参数!$B$3),0,1) -> #VALUE! | K13: =IF($B$2="手动输入",IF($B$3="综合电价",K5,K12),VLOOKUP(地区辅助页!$E$1,IF($B$2="标准1",电价电量取值表!$A:$H,电价电量取值表!$Q:$X),IF(K15>2030,8,K15-2025+3),FALSE))*IF(OR(基本参数!$B$2<=COLUMN()-3,COLUMN()-3<基本参数!$B$3),0,1) -> #VALUE! | ... AB13: =IF($B$2="手动输入",IF($B$3="综合电价",AB5,AB12),VLOOKUP(地区辅助页!$E$1,IF($B$2="标准1",电价电量取值表!$A:$H,电价电量取值表!$Q:$X),IF(AB15>2030,8,AB15-2025+3),FALSE))*IF(OR(基本参数!$B$2<=COLUMN()-3,COLUMN()-3<基本参数!$B$3),0,1) -> #VALUE!
A14: 上网利用小时数 | B14: 小时 | D14: =收入和税金!D10/基本参数!$B$7 -> #VALUE! | E14: =收入和税金!E10/基本参数!$B$7 -> #VALUE! | F14: =收入和税金!F10/基本参数!$B$7 -> #VALUE! | G14: =收入和税金!G10/基本参数!$B$7 -> #VALUE! | H14: =收入和税金!H10/基本参数!$B$7 -> #VALUE! | I14: =收入和税金!I10/基本参数!$B$7 -> #VALUE! | J14: =收入和税金!J10/基本参数!$B$7 -> #VALUE! | K14: =收入和税金!K10/基本参数!$B$7 -> #VALUE! | ... AB14: =收入和税金!AB10/基本参数!$B$7 -> #VALUE!
A15: 年份 | D15: =基本参数!B8 -> 0 | E15: =D15+1 -> 1 | F15: =E15+1 -> 2 | G15: =F15+1 -> 3 | H15: =G15+1 -> 4 | I15: =H15+1 -> 5 | J15: =I15+1 -> 6 | K15: =J15+1 -> 7 | L15: =K15+1 -> 8 | ... AB15: =AA15+1 -> 24
A16: 分项发电量占总发电量比例 | D16: =IF($B$7="占比（%）",D7,D7/D14*100)+IF($B$9="占比（%）",D9,D9/D14*100)+IF($B$11="占比（%）",D11,D11/D14*100) -> 100 | E16: =IF($B$7="占比（%）",E7,E7/E14*100)+IF($B$9="占比（%）",E9,E9/E14*100)+IF($B$11="占比（%）",E11,E11/E14*100) -> 100 | F16: =IF($B$7="占比（%）",F7,F7/F14*100)+IF($B$9="占比（%）",F9,F9/F14*100)+IF($B$11="占比（%）",F11,F11/F14*100) -> 100 | G16: =IF($B$7="占比（%）",G7,G7/G14*100)+IF($B$9="占比（%）",G9,G9/G14*100)+IF($B$11="占比（%）",G11,G11/G14*100) -> 100 | H16: =IF($B$7="占比（%）",H7,H7/H14*100)+IF($B$9="占比（%）",H9,H9/H14*100)+IF($B$11="占比（%）",H11,H11/H14*100) -> 100 | I16: =IF($B$7="占比（%）",I7,I7/I14*100)+IF($B$9="占比（%）",I9,I9/I14*100)+IF($B$11="占比（%）",I11,I11/I14*100) -> 100 | J16: =IF($B$7="占比（%）",J7,J7/J14*100)+IF($B$9="占比（%）",J9,J9/J14*100)+IF($B$11="占比（%）",J11,J11/J14*100) -> 100 | K16: =IF($B$7="占比（%）",K7,K7/K14*100)+IF($B$9="占比（%）",K9,K9/K14*100)+IF($B$11="占比（%）",K11,K11/K14*100) -> 100 | ... AB16: =IF($B$7="占比（%）",AB7,AB7/AB14*100)+IF($B$9="占比（%）",AB9,AB9/AB14*100)+IF($B$11="占比（%）",AB11,AB11/AB14*100) -> 100

Sheet 投资计划与资金筹措表
A1: 投资计划与资金筹措表
A2: 人民币单位：万元
A3: 序号 | B3: 项目 | C3: 合计 | D3: 计算期
D4: 第1年 | E4: 第2年
A5: 1 | B5: 总投资 | C5: =SUM(D5:E5) -> 0 | D5: =SUM(D6:D8) -> 0 | E5: =SUM(E6:E8) -> 0
A6: 1.1 | B6: 建设投资 | C6: =SUM(D6:E6) -> 0 | D6: =基本参数!B12 -> 0 | E6: 0
A7: 1.2 | B7: 建设期利息 | C7: =SUM(D7:E7) -> 0 | D7: =基本参数!B20 -> 0 | E7: 0
A8: 1.3 | B8: 流动资金 | C8: =SUM(D8:E8) -> 0 | D8: =IF(COLUMN()-3=基本参数!$B$3+1,基本参数!$B$7/10*基本参数!$B$27,0) -> 0 | E8: =IF(COLUMN()-3=基本参数!$B$3+1,基本参数!$B$7/10*基本参数!$B$27,0) -> 0
A9: 2 | B9: 资金筹措 | C9: =SUM(D9:E9) -> 0 | D9: =D10+D13 -> 0 | E9: =E10+E13 -> 0
A10: 2.1 | B10: 资本金（资金筹措） | C10: =SUM(D10:E10) -> 0 | D10: =D11+D12 -> 0 | E10: =E11+E12 -> 0
A11: 2.1.1 | B11: 建设投资资本金 | C11: =SUM(D11:E11) -> 0 | D11: =基本参数!$B$17%*(D5-D8) -> 0 | E11: =基本参数!$B$17%*(E5-E8) -> 0
A12: 2.1.2 | B12: 流动资金资本金 | C12: =SUM(D12:E12) -> 0 | D12: =D8*基本参数!$B$28% -> 0 | E12: =E8*基本参数!$B$28% -> 0
A13: 2.2 | B13: 借款 | C13: =SUM(D13:E13) -> 0 | D13: =D14+D17 -> 0 | E13: =E14+E17 -> 0
A14: 2.2.1 | B14: 长期借款 | C14: =SUM(D14:E14) -> 0 | D14: =SUM(D15:D16) -> 0 | E14: =SUM(E15:E16) -> 0
B15: 长期借款本金 | C15: =SUM(D15:E15) -> 0 | D15: =D6-D11 -> 0 | E15: =E6-E11 -> 0
B16: 建设期利息 | C16: =SUM(D16:E16) -> 0 | D16: =D7 -> 0 | E16: =E7 -> 0
A17: 2.2.2 | B17: 流动资金借款 | C17: =SUM(D17:E17) -> 0 | D17: =D8-D12 -> 0 | E17: =E8-E12 -> 0

Sheet 总成本费用表
A1: 总成本费用表
A2: 人民币单位：万元
A3: 序号 | B3: 项目 | C3: 合计 | D3: 建设期 | E3: 运行期
D4: 第1年 | E4: 第2年 | F4: 第3年 | G4: 第4年 | H4: 第5年 | I4: 第6年 | J4: 第7年 | K4: 第8年 | L4: 第9年 | M4: 第10年 | N4: 第11年 | O4: 第12年 | P4: 第13年 | Q4: 第14年 | R4: 第15年 | S4: 第16年 | T4: 第17年 | U4: 第18年 | V4: 第19年 | W4: 第20年 | X4: 第21年 | Y4: 第22年 | Z4: 第23年 | AA4: 第24年 | AB4: 第25年 | AC4: 第26年
A5: 1 | B5: 折旧费 | C5: =SUM(D5:AC5) -> 0 | D5: =成本费用!C8 -> 0 | E5: =成本费用!D8 -> 0 | F5: =成本费用!E8 -> 0 | G5: =成本费用!F8 -> 0 | H5: =成本费用!G8 -> 0 | I5: =成本费用!H8 -> 0 | J5: =成本费用!I8 -> 0 | K5: =成本费用!J8 -> 0 | ... AC5: =成本费用!AB8 -> 0
A6: 2 | B6: 维修费 | C6: =SUM(D6:AC6) -> #REF! | D6: =成本费用!C17 -> 0 | E6: =成本费用!D17 -> #REF! | F6: =成本费用!E17 -> #REF! | G6: =成本费用!F17 -> #REF! | H6: =成本费用!G17 -> #REF! | I6: =成本费用!H17 -> #REF! | J6: =成本费用!I17 -> #REF! | K6: =成本费用!J17 -> #REF! | ... AC6: =成本费用!AB17 -> #REF!
A7: 3 | B7: 工资及福利 | C7: =SUM(D7:AC7) -> #REF! | D7: =成本费用!C25 -> 0 | E7: =成本费用!D25 -> #REF! | F7: =成本费用!E25 -> #REF! | G7: =成本费用!F25 -> #REF! | H7: =成本费用!G25 -> #REF! | I7: =成本费用!H25 -> #REF! | J7: =成本费用!I25 -> #REF! | K7: =成本费用!J25 -> #REF! | ... AC7: =成本费用!AB25 -> #REF!
A8: 4 | B8: 保险费 | C8: =SUM(D8:AC8) -> #REF! | D8: =成本费用!C33 -> 0 | E8: =成本费用!D33 -> #REF! | F8: =成本费用!E33 -> #REF! | G8: =成本费用!F33 -> #REF! | H8: =成本费用!G33 -> #REF! | I8: =成本费用!H33 -> #REF! | J8: =成本费用!I33 -> #REF! | K8: =成本费用!J33 -> #REF! | ... AC8: =成本费用!AB33 -> #REF!
A9: 5 | B9: 材料费 | C9: =SUM(D9:AC9) -> #REF! | D9: =成本费用!C40 -> 0 | E9: =成本费用!D40 -> #REF! | F9: =成本费用!E40 -> #REF! | G9: =成本费用!F40 -> #REF! | H9: =成本费用!G40 -> #REF! | I9: =成本费用!H40 -> #REF! | J9: =成本费用!I40 -> #REF! | K9: =成本费用!J40 -> #REF! | ... AC9: =成本费用!AB40 -> #REF!
A10: 6 | B10: 委托运维费 | C10: =SUM(D10:AC10) -> #DIV/0! | D10: =成本费用!C47 -> 0 | E10: =成本费用!D47 -> #DIV/0! | F10: =成本费用!E47 -> #DIV/0! | G10: =成本费用!F47 -> #DIV/0! | H10: =成本费用!G47 -> #DIV/0! | I10: =成本费用!H47 -> #DIV/0! | J10: =成本费用!I47 -> #DIV/0! | K10: =成本费用!J47 -> #DIV/0! | ... AC10: =成本费用!AB47 -> #DIV/0!
A11: 7 | B11: 摊销费 | C11: =SUM(D11:AC11) -> 0 | D11: =成本费用!C56 -> 0 | E11: =成本费用!D56 -> 0 | F11: =成本费用!E56 -> 0 | G11: =成本费用!F56 -> 0 | H11: =成本费用!G56 -> 0 | I11: =成本费用!H56 -> 0 | J11: =成本费用!I56 -> 0 | K11: =成本费用!J56 -> 0 | ... AC11: =成本费用!AB56 -> 0
A12: 8 | B12: 利息支出 | C12: =SUM(D12:AC12) -> #VALUE! | D12: =借款还本付息计划表!D13+借款还本付息计划表!D9+借款还本付息计划表!D19 -> 0 | E12: =借款还本付息计划表!E13+借款还本付息计划表!E9+借款还本付息计划表!E19 -> 0 | F12: =借款还本付息计划表!F13+借款还本付息计划表!F9+借款还本付息计划表!F19 -> #VALUE! | G12: =借款还本付息计划表!G13+借款还本付息计划表!G9+借款还本付息计划表!G19 -> #VALUE! | H12: =借款还本付息计划表!H13+借款还本付息计划表!H9+借款还本付息计划表!H19 -> #VALUE! | I12: =借款还本付息计划表!I13+借款还本付息计划表!I9+借款还本付息计划表!I19 -> #VALUE! | J12: =借款还本付息计划表!J13+借款还本付息计划表!J9+借款还本付息计划表!J19 -> #VALUE! | K12: =借款还本付息计划表!K13+借款还本付息计划表!K9+借款还本付息计划表!K19 -> #VALUE! | ... AC12: =借款还本付息计划表!AC13+借款还本付息计划表!AC9+借款还本付息计划表!AC19 -> #VALUE!
A13: 9 | B13: 其他费用 | C13: =SUM(D13:AC13) -> #REF! | D13: =成本费用!C66 -> 0 | E13: =成本费用!D66 -> #REF! | F13: =成本费用!E66 -> #REF! | G13: =成本费用!F66 -> #REF! | H13: =成本费用!G66 -> #REF! | I13: =成本费用!H66 -> #REF! | J13: =成本费用!I66 -> #REF! | K13: =成本费用!J66 -> #REF! | ... AC13: =成本费用!AB66 -> #REF!
A14: 9.1 | B14: 其他费用 | C14: =SUM(D14:AC14) -> #REF! | D14: =成本费用!C60 -> 0 | E14: =成本费用!D60 -> #REF! | F14: =成本费用!E60 -> #REF! | G14: =成本费用!F60 -> #REF! | H14: =成本费用!G60 -> #REF! | I14: =成本费用!H60 -> #REF! | J14: =成本费用!I60 -> #REF! | K14: =成本费用!J60 -> #REF! | ... AC14: =成本费用!AB60 -> #REF!
A15: 9.2 | B15: =成本费用!A61 -> 其他费用1 | C15: =SUM(D15:AC15) -> 0 | D15: =成本费用!C61 -> 0 | E15: =成本费用!D61 -> 0 | F15: =成本费用!E61 -> 0 | G15: =成本费用!F61 -> 0 | H15: =成本费用!G61 -> 0 | I15: =成本费用!H61 -> 0 | J15: =成本费用!I61 -> 0 | K15: =成本费用!J61 -> 0 | ... AC15: =成本费用!AB61 -> 0
A16: 9.3 | B16: =成本费用!A62 -> 其他费用2 | C16: =SUM(D16:AC16) -> 0 | D16: =成本费用!C62 -> 0 | E16: =成本费用!D62 -> 0 | F16: =成本费用!E62 -> 0 | G16: =成本费用!F62 -> 0 | H16: =成本费用!G62 -> 0 | I16: =成本费用!H62 -> 0 | J16: =成本费用!I62 -> 0 | K16: =成本费用!J62 -> 0 | ... AC16: =成本费用!AB62 -> 0
A17: 9.4 | B17: =成本费用!A63 -> 其他费用3 | C17: =SUM(D17:AC17) -> 0 | D17: =成本费用!C63 -> 0 | E17: =成本费用!D63 -> 0 | F17: =成本费用!E63 -> 0 | G17: =成本费用!F63 -> 0 | H17: =成本费用!G63 -> 0 | I17: =成本费用!H63 -> 0 | J17: =成本费用!I63 -> 0 | K17: =成本费用!J63 -> 0 | ... AC17: =成本费用!AB63 -> 0
A18: 9.5 | B18: 其他费用4 | C18: =SUM(D18:AC18) -> 0 | D18: =成本费用!C64 -> 0 | E18: =成本费用!D64 -> 0 | F18: =成本费用!E64 -> 0 | G18: =成本费用!F64 -> 0 | H18: =成本费用!G64 -> 0 | I18: =成本费用!H64 -> 0 | J18: =成本费用!I64 -> 0 | K18: =成本费用!J64 -> 0 | ... AC18: =成本费用!AB64 -> 0
A19: 9.6 | B19: 其他费用5 | C19: =SUM(D19:AC19) -> 0 | D19: =成本费用!C65 -> 0 | E19: =成本费用!D65 -> 0 | F19: =成本费用!E65 -> 0 | G19: =成本费用!F65 -> 0 | H19: =成本费用!G65 -> 0 | I19: =成本费用!H65 -> 0 | J19: =成本费用!I65 -> 0 | K19: =成本费用!J65 -> 0 | ... AC19: =成本费用!AB65 -> 0
A20: 10 | B20: 总成本费用 | C20: =SUM(D20:AC20) -> #REF! | D20: =D21+D5+D11+D12 -> 0 | E20: =E21+E5+E11+E12 -> #REF! | F20: =F21+F5+F11+F12 -> #REF! | G20: =G21+G5+G11+G12 -> #REF! | H20: =H21+H5+H11+H12 -> #REF! | I20: =I21+I5+I11+I12 -> #REF! | J20: =J21+J5+J11+J12 -> #REF! | K20: =K21+K5+K11+K12 -> #REF! | ... AC20: =AC21+AC5+AC11+AC12 -> #REF!
A21: 11 | B21: 经营成本 | C21: =SUM(D21:AC21) -> #REF! | D21: =D6+D7+D8+D9+D10+D13 -> 0 | E21: =E6+E7+E8+E9+E10+E13 -> #REF! | F21: =F6+F7+F8+F9+F10+F13 -> #REF! | G21: =G6+G7+G8+G9+G10+G13 -> #REF! | H21: =H6+H7+H8+H9+H10+H13 -> #REF! | I21: =I6+I7+I8+I9+I10+I13 -> #REF! | J21: =J6+J7+J8+J9+J10+J13 -> #REF! | K21: =K6+K7+K8+K9+K10+K13 -> #REF! | ... AC21: =AC6+AC7+AC8+AC9+AC10+AC13 -> #REF!
A22: 12 | B22: 固定成本(无材料费) | C22: =SUM(D22:AC22) -> #REF! | D22: =D5+D6+D7+D8+D10+D11+D12+D13 -> 0 | E22: =E5+E6+E7+E8+E10+E11+E12+E13 -> #REF! | F22: =F5+F6+F7+F8+F10+F11+F12+F13 -> #REF! | G22: =G5+G6+G7+G8+G10+G11+G12+G13 -> #REF! | H22: =H5+H6+H7+H8+H10+H11+H12+H13 -> #REF! | I22: =I5+I6+I7+I8+I10+I11+I12+I13 -> #REF! | J22: =J5+J6+J7+J8+J10+J11+J12+J13 -> #REF! | K22: =K5+K6+K7+K8+K10+K11+K12+K13 -> #REF! | ... AC22: =AC5+AC6+AC7+AC8+AC10+AC11+AC12+AC13 -> #REF!
A23: 13 | B23: 可变成本 | C23: =SUM(D23:AC23) -> #REF! | D23: =D9 -> 0 | E23: =E9 -> #REF! | F23: =F9 -> #REF! | G23: =G9 -> #REF! | H23: =H9 -> #REF! | I23: =I9 -> #REF! | J23: =J9 -> #REF! | K23: =K9 -> #REF! | ... AC23: =AC9 -> #REF!

Sheet 借款还本付息计划表
A1: 借款还本付息计划表
A2: 人民币单位：万元
A3: 序号 | B3: 项目 | C3: 合计 | D3: 建设期 | E3: 运行期
D4: 第1年 | E4: 第2年 | F4: 第3年 | G4: 第4年 | H4: 第5年 | I4: 第6年 | J4: 第7年 | K4: 第8年 | L4: 第9年 | M4: 第10年 | N4: 第11年 | O4: 第12年 | P4: 第13年 | Q4: 第14年 | R4: 第15年 | S4: 第16年 | T4: 第17年 | U4: 第18年 | V4: 第19年 | W4: 第20年 | X4: 第21年 | Y4: 第22年 | Z4: 第23年 | AA4: 第24年 | AB4: 第25年 | AC4: 第26年
A5: 1 | B5: 长期借款 | C5: =SUM(D5:AC5) -> 0 | D5: =投资计划与资金筹措表!D14 -> 0 | E5: =投资计划与资金筹措表!E14 -> 0
A6: 1.1 | B6: 年初借款余额 | D6: =IF(基本参数!$B$35="约定还款",成本费用!C85,IF(基本参数!$B$35="等额还本付息",成本费用!C82,成本费用!C78)) -> 0 | E6: =IF(基本参数!$B$35="约定还款",成本费用!D85,IF(基本参数!$B$35="等额还本付息",成本费用!D82,成本费用!D78)) -> 0 | F6: =IF(基本参数!$B$35="约定还款",成本费用!E85,IF(基本参数!$B$35="等额还本付息",成本费用!E82,成本费用!E78)) -> 0 | G6: =IF(基本参数!$B$35="约定还款",成本费用!F85,IF(基本参数!$B$35="等额还本付息",成本费用!F82,成本费用!F78)) -> 0 | H6: =IF(基本参数!$B$35="约定还款",成本费用!G85,IF(基本参数!$B$35="等额还本付息",成本费用!G82,成本费用!G78)) -> 0 | I6: =IF(基本参数!$B$35="约定还款",成本费用!H85,IF(基本参数!$B$35="等额还本付息",成本费用!H82,成本费用!H78)) -> 0 | J6: =IF(基本参数!$B$35="约定还款",成本费用!I85,IF(基本参数!$B$35="等额还本付息",成本费用!I82,成本费用!I78)) -> 0 | K6: =IF(基本参数!$B$35="约定还款",成本费用!J85,IF(基本参数!$B$35="等额还本付息",成本费用!J82,成本费用!J78)) -> 0 | ... AC6: =IF(基本参数!$B$35="约定还款",成本费用!AB85,IF(基本参数!$B$35="等额还本付息",成本费用!AB82,成本费用!AB78)) -> 0
A7: 1.2 | B7: 当期还本付息 | C7: =SUM(D7:AC7) -> 0 | D7: =D8+D9 -> 0 | E7: =E8+E9 -> 0 | F7: =F8+F9 -> 0 | G7: =G8+G9 -> 0 | H7: =H8+H9 -> 0 | I7: =I8+I9 -> 0 | J7: =J8+J9 -> 0 | K7: =K8+K9 -> 0 | ... AC7: =AC8+AC9 -> 0
A8: 1.2.1 | B8: 本年还本 | C8: =SUM(D8:AC8) -> 0 | D8: =IF(基本参数!$B$35="约定还款",成本费用!C86,IF(基本参数!$B$35="等额还本付息",成本费用!C83,成本费用!C79)) -> 0 | E8: =IF(基本参数!$B$35="约定还款",成本费用!D86,IF(基本参数!$B$35="等额还本付息",成本费用!D83,成本费用!D79)) -> 0 | F8: =IF(基本参数!$B$35="约定还款",成本费用!E86,IF(基本参数!$B$35="等额还本付息",成本费用!E83,成本费用!E79)) -> 0 | G8: =IF(基本参数!$B$35="约定还款",成本费用!F86,IF(基本参数!$B$35="等额还本付息",成本费用!F83,成本费用!F79)) -> 0 | H8: =IF(基本参数!$B$35="约定还款",成本费用!G86,IF(基本参数!$B$35="等额还本付息",成本费用!G83,成本费用!G79)) -> 0 | I8: =IF(基本参数!$B$35="约定还款",成本费用!H86,IF(基本参数!$B$35="等额还本付息",成本费用!H83,成本费用!H79)) -> 0 | J8: =IF(基本参数!$B$35="约定还款",成本费用!I86,IF(基本参数!$B$35="等额还本付息",成本费用!I83,成本费用!I79)) -> 0 | K8: =IF(基本参数!$B$35="约定还款",成本费用!J86,IF(基本参数!$B$35="等额还本付息",成本费用!J83,成本费用!J79)) -> 0 | ... AC8: =IF(基本参数!$B$35="约定还款",成本费用!AB86,IF(基本参数!$B$35="等额还本付息",成本费用!AB83,成本费用!AB79)) -> 0
A9: 1.2.2 | B9: 本年付息 | C9: =SUM(D9:AC9) -> 0 | D9: =IF(基本参数!$B$35="约定还款",成本费用!C87,IF(基本参数!$B$35="等额还本付息",成本费用!C84,成本费用!C80)) -> 0 | E9: =IF(基本参数!$B$35="约定还款",成本费用!D87,IF(基本参数!$B$35="等额还本付息",成本费用!D84,成本费用!D80)) -> 0 | F9: =IF(基本参数!$B$35="约定还款",成本费用!E87,IF(基本参数!$B$35="等额还本付息",成本费用!E84,成本费用!E80)) -> 0 | G9: =IF(基本参数!$B$35="约定还款",成本费用!F87,IF(基本参数!$B$35="等额还本付息",成本费用!F84,成本费用!F80)) -> 0 | H9: =IF(基本参数!$B$35="约定还款",成本费用!G87,IF(基本参数!$B$35="等额还本付息",成本费用!G84,成本费用!G80)) -> 0 | I9: =IF(基本参数!$B$35="约定还款",成本费用!H87,IF(基本参数!$B$35="等额还本付息",成本费用!H84,成本费用!H80)) -> 0 | J9: =IF(基本参数!$B$35="约定还款",成本费用!I87,IF(基本参数!$B$35="等额还本付息",成本费用!I84,成本费用!I80)) -> 0 | K9: =IF(基本参数!$B$35="约定还款",成本费用!J87,IF(基本参数!$B$35="等额还本付息",成本费用!J84,成本费用!J80)) -> 0 | ... AC9: =IF(基本参数!$B$35="约定还款",成本费用!AB87,IF(基本参数!$B$35="等额还本付息",成本费用!AB84,成本费用!AB80)) -> 0
A10: 1.3 | B10: 期末借款余额 | D10: =D5+D6-D8 -> 0 | E10: =E5+E6-E8 -> 0 | F10: =F5+F6-F8 -> 0 | G10: =G5+G6-G8 -> 0 | H10: =H5+H6-H8 -> 0 | I10: =I5+I6-I8 -> 0 | J10: =J5+J6-J8 -> 0 | K10: =K5+K6-K8 -> 0 | ... AC10: =AC5+AC6-AC8 -> 0
A11: 2 | B11: 流动资金借款 | C11: =SUM(D11:AC11) -> 0 | D11: =投资计划与资金筹措表!D17 -> 0 | E11: =投资计划与资金筹措表!E17 -> 0
A12: 2.1 | B12: 流动资金借款累计 | D12: =SUM($D$11:D11) -> 0 | E12: =SUM($D$11:E11) -> 0 | F12: =SUM($D$11:F11) -> 0 | G12: =SUM($D$11:G11) -> 0 | H12: =SUM($D$11:H11) -> 0 | I12: =SUM($D$11:I11) -> 0 | J12: =SUM($D$11:J11) -> 0 | K12: =SUM($D$11:K11) -> 0 | ... AC12: =SUM($D$11:AC11) -> 0
A13: 2.2 | B13: 流动资金利息 | C13: =SUM(D13:AC13) -> 0 | D13: =D12*基本参数!$B$29% -> 0 | E13: =E12*基本参数!$B$29% -> 0 | F13: =F12*基本参数!$B$29% -> 0 | G13: =G12*基本参数!$B$29% -> 0 | H13: =H12*基本参数!$B$29% -> 0 | I13: =I12*基本参数!$B$29% -> 0 | J13: =J12*基本参数!$B$29% -> 0 | K13: =K12*基本参数!$B$29% -> 0 | ... AC13: =AC12*基本参数!$B$29% -> 0
