Workbook

Sheet 01风电造价标准调整
A1: 序号 | B1: 项目名称 | C1: 单位 | D1: 陆上风电（MW） | J1: 海上风电（MW) | M1: 造价调整值 | N1: 装机容量（MW） | O1: =(21+17)*10.5 -> 399 | P1: 单位千瓦 动态投资 | Q1: 可比投资
D2: 50 | E2: 50 | F2: 100 | G2: 200 | H2: 500 | I2: 1000 | J2: 300 | K2: 500 | L2: 1000 | M2: =SUM(M3:M84) -> 10272.361 | N2: 可研动态（万元） | O2: =SUM(O3:O8)+O10+O11 -> 417828.77 | P2: =O2/O1*10 -> 10471.899 | Q2: =(O2-O10-O11)/O1*10 -> 10248.271
A3: 1 | B3: 基本方案标准值 | N3: 施工辅助工程 | O3: =5858+5614 -> 11472
A4: 1.1 | B4: 平原 | C4: 元/kW | D4: 5076 | E4: 4524 | F4: 4341 | G4: 4201 | H4: 4121 | I4: 4080 | J4: —— | N4: 设备及安装工程 | O4: =99920+124495 -> 224415
A5: 1.2 | B5: 山地 | C5: 元/kW | E5: 5027 | F5: 4838 | G5: 4532 | H5: 4370 | I5: —— | N5: 建筑工程 | O5: =50765+54138 -> 104903
A6: 1.3 | B6: 复杂山地 | C6: 元/kW | D6: —— | E6: 5419 | F6: 5203 | G6: 4912 | H6: 4795 | I6: —— | N6: 其他费用 | O6: =34831+19975 -> 54806
A7: 1.4 | B7: 辽宁、河北及山东区域 | C7: 元/kW | D7: —— | J7: 10977 | K7: 9981 | L7: 9399 | M7: =TREND(J7:K7,J2:K2,O1) -> 10483.98 | N7: 基本预备费 | O7: =3827+4051 -> 7878
A8: 1.5 | B8: 江苏、浙江区域 | C8: 元/kW | J8: 11052 | K8: 10044 | L8: 9455 | N8: 建设期贷款利息 | O8: =2541+2891 -> 5432
A9: 1.6 | B9: 福建、粤西区域 | C9: 元/kW | J9: 12132 | K9: 11049 | L9: 10393 | N9: 利率 | O9: 0.035
A10: 1.7 | B10: 粤西、广西及海南区域 | C10: 元/kW | J10: 11490 | K10: 10461 | L10: 9836 | N10: 其他 | O10: =2000+5000+1800 -> 8800
A11: 2 | B11: 千瓦造价调整模块 | N11: 其他（建设期利息） | O11: =O10*80%*O9/(2*12/12+20%*O9) -> 122.7703
A12: 2.1 | B12: 风机设备价格调整
A13: 2.1.1 | B13: 风机设备价格（含塔筒和锚栓） | C13: 元/kW | D13: 以实际价格替代（陆风设备2100元/kW，海风设备3500元/kW） | M13: =N13-3500 -> 55 | N13: 3555
A14: 2.2 | B14: 风机建安费调整 | C14: 如机型不匹配参照相近机型 | N14: 38台10.5MW风电机组
A15: 2.2.1 | B15: 6.x MW机组建安费 | C15: 元/kW | D15: -61.54 | J15: ——
A16: 2.2.2 | B16: 7.x MW机组建安费 | C16: 元/kW | D16: -53.33 | J16: ——
A17: 2.2.3 | B17: 8MW机组建安费 | C17: 元/kW | D17: —— | J17: 100 | K17: 100 | L17: 100
A18: 2.2.4 | B18: 11MW机组建安费 | C18: 元/kW | J18: 0 | K18: 0 | L18: 0 | M18: =0 -> 0
A19: 2.2.5 | B19: 12MW机组建安费 | C19: 元/kW | J19: -10 | K19: -10 | L19: -10
A20: 2.2.6 | B20: 14MW机组建安费 | C20: 元/kW | J20: -20 | K20: -20 | L20: -20
A21: 2.2.7 | B21: 16MW机组建安费 | C21: 元/kW | J21: -7 | K21: -7 | L21: -7
A22: 2.3 | B22: 塔筒建安费调整 | N22: 轮毂高度142m
A23: 2.3.1 | B23: 钢塔筒轮毂高度100—120m | C23: 万元/台 | D23: —— | E23: 0 | F23: 0 | G23: 0 | H23: 0 | I23: 0 | J23: ——
A24: 2.3.2 | B24: 钢塔筒轮毂高度140m（含＞120m） | C24: 万元/台 | D24: —— | E24: 10 | F24: 10 | G24: 10 | H24: 10 | I24: 10 | J24: ——
A25: 2.3.3 | B25: 混塔轮毂高度140m | C25: 万元/台 | D25: —— | E25: 20 | F25: 20 | G25: 20 | H25: 20 | I25: 20 | J25: ——
A26: 2.3.4 | B26: 混塔轮毂高度160m | C26: 万元/台 | D26: —— | E26: 30 | F26: 30 | G26: 30 | H26: 30 | I26: 30 | J26: ——
A27: 2.4 | B27: 风机基础建安费调整 | N27: 单桩基础无嵌岩，桩长79m
A28: 2.4.1 | B28: PHC管桩（桩径600mm） | C28: 元/m | D28: 460 | J28: ——
A29: 2.4.2 | B29: 灌注桩（桩径800mm） | C29: 元/m | D29: 750 | J29: ——
A30: 2.4.3 | B30: 非嵌岩单桩（含材料费） | C30: 元/m | D30: —— | J30: 230200 | M30: =(79*38-100*27)*J30/(O1*10^3) -> 174.23659
A31: 2.4.4 | B31: 嵌岩单桩（含材料费） | C31: 元/m | J31: 350000
A32: 2.4.5 | B32: 导管架形式（含材料费） | C32: 元/m | J32: 330000
A33: 2.5 | B33: 机组变电站调整 | M33: 0
A34: 2.5.1 | B34: 油变 | C34: 元/kW | D34: -20 | J34: ——
A35: 2.6 | B35: 集电线路安装费调整 | C35: 根据线路实际长度调整 | M35: 0
A36: 2.6.1 | B36: 架空线路（铝导线）平原-单回 | C36: 元/km | D36: —— | E36: 450000 | J36: ——
A37: 2.6.2 | B37: 架空线路（铝导线）山地-单回 | C37: 元/km | D37: —— | E37: 520000 | J37: ——
A38: 2.6.3 | B38: 架空线路（铝导线）复杂山地-单回 | C38: 元/km | D38: —— | E38: 650000 | J38: ——
A39: 2.6.4 | B39: 架空线路（铝导线）平原-双回 | C39: 元/km | D39: —— | E39: 765000 | J39: ——
A40: 2.6.5 | B40: 架空线路（铝导线）山地-双回 | C40: 元/km | D40: —— | E40: 884000 | J40: ——
...

Sheet 02基本方案
A1: 序号 | B1: 名称 | C1: 陆上风电 | H1: 海上风电
C2: 50MW | D2: 100MW | E2: 200MW | F2: 500MW | G2: 1000MW | H2: 300MW | I2: 500MW | J2: 1000MW
A3: 一 | B3: 风力发电机组 | C3: （1）10台，5MW/台 | D3: （1）20台，5MW/台 | E3: （1）40台，5MW/台 | F3: （1）100台，5MW/台 | G3: （1）200台，5MW/台 | H3: （1）27台，11MW/台 | I3: （1）45台，11MW/台 | J3: （1）91台，11MW/台
C4: （2）叶轮直径为191-200m，轮毂高度为120m | H4: （2）叶轮直径为208m，轮毂高度为130m
A5: 二 | B5: 塔筒（架） | C5: 钢制塔筒
A6: 三 | B6: 风电机组基础 | C6: （1）风机基础采用现浇钢筋混凝土圆形独立基础或扩展基础 （2）基础混凝土强度等级取C40，抗冻等级F200，主受力钢筋强度等级为HRB400 | H6: （1）风机基础采用单桩基础，与风机塔筒连接处外径8.5m，水中部分通过锥形段过渡到10.5m，泥面以下为单根直径10.5m 钢管桩定位于海底，每根长度约100m，无嵌岩，以砂或黏土及以下地层作为桩基持力层 （2）场址区域水深：30m～35m，场址中心离岸距离30～35km
A7: 四 | B7: 机组变电站 | C7: （1）采用一机一变电气接线方式，选择干式箱式变电站变压器容量5250kVA，高压侧电压选用35kV等级 （2）选用箱变容量S18-5250/37，37±2×2.5%/1.14kV （3）箱式变压器基础采用现浇钢筋混凝土箱型结构，混凝土强度等级为C30，天然地基 | H7: （1）机组变电站升压至66kV，设置于机舱内
A8: 五 | B8: 集电线路 | C8: （1）集电线路和箱式变压器高压侧电压选用35kV等级 （2）集电线路采用电缆加架空方式 （3）集电线路箱变与架空线之间、架空线与35kV开关柜之间采用铝芯电缆 （4）架空部分导线型式采用钢芯铝绞线 （5）无跨越铁路、公路、河流湖泊、高压线路等情况 | H8: （1）集电线路选用66kV等级交流交联聚乙烯三芯海缆 （2）66kV海缆接入海上升压站
C9: （5）35kV电缆：平原5.7km，山地6.05km，复杂山地10.9km； 架空线路：单双回比例为8:1，其中平原13.8km，山地18.0km，复杂山地24.2km | D9: （5）35kV电缆：平原11.4km，山地14.3km，复杂山地21.8km； 架空线路：单双回比例为8:1，其中平原27.6km，山地36km，复杂山地50.4km | E9: （5）35kV电缆：平原29.6km，山地29.0km，复杂山地43.6km； 架空线路：单双回比例为8:1，其中平原71.7km，山地77.0km，复杂山地95.4km | F9: （5）35kV电缆：平原74.1km，山地82km，复杂山地113.3km； 架空线路：单双回比例为8:1，其中平原179.4km，山地198.9km，复杂山地242.4km | G9: （5）35kV电缆：平原148.2km； 架空线路：单双回比例为8:1，平原358.8km | H9: （3）线路长度为路径长度，共计55km | I9: （3）线路长度为路径长度，共计107km | J9: （3）线路长度为路径长度，共计170km
A10: 六 | B10: 升压变电站工程（送出海缆） | C10: （1）站内动力电缆采用铜芯电缆 （2）站内道路采用4.5m水泥混凝土路面，转弯半径为9m；站内电缆沟采用钢筋混凝土结构 （3）升压站基础均为天然地基，综合楼及附属用房均采用常规建筑型式，电气室采用预制舱形式 | H10: （1）一座陆上集控中心
C11: （4）配套新建一座110kV升压站，配置1台50MVA主变 | D11: （4）配套新建一座110kV升压站，配置1台100MVA主变 | E11: （4）配套新建一座220kV升压站，配置2台100MVA主变 | F11: （4）配套新建一座220kV升压站，配置3台170MVA主变 | G11: （4）配套新建一座330kV升压站，配置4台250MVA主变 | H11: （2）建筑面积6139m2，220kV （3）配套新建一座220kV海上升压站，配置2台160MVA主变。2条220kV三芯三相交流光电复合海缆3x800mm2送出至岸上，距离40km，其中登陆距离1.2km | I11: （2）建筑面积6283m2，220kV （3）配套新建一座220kV海升压站，配置2台270MVA主变。2条220kV三芯三相交流光电复合海缆3x800mm2送出至岸上，距离40km，其中登陆距离1.2km | J11: （2）建筑面积7254m2，500kV （3）配套新建一座500kV海升压站，配置2台550MVA主变。2条550kV三芯三相交流光电复合海缆3x800mm2送出至岸上，距离40km，其中登陆距离1.2km
A12: 七 | B12: 交通工程 | C12: （1）进场道路考虑从场外既有道路引接，进站道路采用厚度为210mm的水泥混凝土路面，路面宽4m，路基宽5m | H12: （1）进集控中心道路考虑从场外既有道路引接，采用厚度为210mm的水泥混凝土路面，路面宽4m，路基宽5m
C13: （2）新建场区道路，其中平原13.5km，山地22km，复杂山地23.5km | D13: （2）新建场区道路，其中平原28km，山地45km，复杂山地48km | E13: （2）新建场区道路，其中平原55.8km，山地70km，复杂山地80km | F13: （2）新建场区道路，其中平原141.7km，山地160km，复杂山地196km | G13: （2）新建场区道路，平原229.3km

Sheet 03造价参考值
A1: 项目类型 | C1: 陆上风电 | Q1: 海上风电 | AC1: 实际造价 | AD1: 单位千瓦造价值对比
A2: 容量（MW） | C2: 50MW 分散式 | D2: 50MW | G2: 100MW | J2: 200MW | M2: 500MW | P2: 1000MW | Q2: 300MW | U2: 500MW | Y2: 1000MW
A3: 地形 | C3: 山地 | D3: 平原 | E3: 山地 | F3: 复杂山地 | G3: 平原 | H3: 山地 | I3: 复杂山地 | J3: 平原 | K3: 山地 | L3: 复杂山地 | M3: 平原 | N3: 山地 | O3: 复杂山地 | P3: 平原 | Q3: 辽宁、河北及山东区域 | R3: 江苏、浙江区域 | S3: 福建、粤东区域 | T3: 粤西、广西及海南区域 | U3: 辽宁、河北及山东区域 | V3: 江苏、浙江区域 | W3: 福建、粤东区域 | X3: 粤西、广西及海南区域 | Y3: 辽宁、河北及山东区域 | Z3: 江苏、浙江区域 | AA3: 福建、粤东区域 | AB3: 粤西、广西及海南区域 | AD3: 实际 | AE3: 标准值
A4: 序号 | B4: 项目名称
A5: 一 | B5: 施工辅助工程（万元） | C5: 538 | D5: 322 | E5: 540 | F5: 621 | G5: 637 | H5: 1039 | I5: 1203 | J5: 1263 | K5: 1982 | L5: 2346 | M5: 3159 | N5: 4392 | O5: 5328 | P5: 6317 | Q5: 6834 | R5: 6904 | S5: 6783 | T5: 7001 | U5: 8424 | V5: 8528 | W5: 9410 | X5: 8609 | Y5: 11696 | Z5: 11825 | AA5: 12594 | AB5: 11953 | AC5: =SUM(AC6:AC11) -> 1754.17 | AD5: =AC5/100*10 -> 175.417 | AE5: =I5/100*10 -> 120.3
A6: 1 | B6: 施工交通工程（万元） | C6: 40 | D6: 5 | E6: 40 | F6: 40 | G6: 8 | H6: 60 | I6: 60 | J6: 11 | K6: 72 | L6: 90 | M6: 28 | N6: 130 | O6: 225 | P6: 56 | Q6: 1800 | R6: 1800 | S6: 1800 | T6: 1800 | U6: 1800 | V6: 1800 | W6: 1800 | X6: 1800 | Y6: 2040 | Z6: 2040 | AA6: 2040 | AB6: 2040 | AC6: 220 | AD6: =AC6/100*10 -> 22 | AE6: =I6/100*10 -> 6
A7: 2 | B7: 施工供电工程（万元） | C7: 40 | D7: 10 | E7: 40 | F7: 40 | G7: 15 | H7: 60 | I7: 60 | J7: 23 | K7: 72 | L7: 90 | M7: 56 | N7: 130 | O7: 225 | P7: 113 | Q7: —— | R7: —— | S7: —— | T7: —— | U7: —— | V7: —— | W7: —— | X7: —— | Y7: —— | Z7: —— | AA7: —— | AB7: —— | AC7: 35 | AD7: =AC7/100*10 -> 3.5 | AE7: =I7/100*10 -> 6
A8: 3 | B8: 风电机组安装平台工程（万元） | C8: 123 | D8: 86 | E8: 123 | F8: 148 | G8: 173 | H8: 246 | I8: 296 | J8: 345 | K8: 493 | L8: 592 | M8: 864 | N8: 1231 | O8: 1480 | P8: 1727 | Q8: —— | R8: —— | S8: —— | T8: —— | U8: —— | V8: —— | W8: —— | X8: —— | Y8: —— | Z8: —— | AA8: —— | AB8: —— | AC8: 823.08 | AD8: =AC8/100*10 -> 82.308 | AE8: =I8/100*10 -> 29.6
B9: 大型船舶（机械）进出场（万元） | C9: —— | D9: —— | E9: —— | F9: —— | G9: —— | H9: —— | I9: —— | J9: —— | K9: —— | L9: —— | M9: —— | N9: —— | O9: —— | P9: —— | Q9: 1550 | R9: 1550 | S9: 1550 | T9: 1550 | U9: 1860 | V9: 1860 | W9: 1860 | X9: 1860 | Y9: 2700 | Z9: 2700 | AA9: 2700 | AB9: 2700
A10: 4 | B10: 其他施工辅助工程（万元） | C10: 105 | D10: 40 | E10: 105 | F10: 125 | G10: 80 | H10: 210 | I10: 250 | J10: 160 | K10: 420 | L10: 500 | M10: 400 | N10: 1050 | O10: 1250 | P10: 800 | Q10: 560 | R10: 560 | S10: 560 | T10: 560 | U10: 560 | V10: 560 | W10: 560 | X10: 560 | Y10: 800 | Z10: 800 | AA10: 800 | AB10: 800 | AC10: 258.53 | AD10: =AC10/100*10 -> 25.853 | AE10: =I10/100*10 -> 25
A11: 5 | B11: 安全文明施工措施（万元） | C11: 230 | D11: 181 | E11: 231 | F11: 268 | G11: 362 | H11: 463 | I11: 537 | J11: 724 | K11: 926 | L11: 1074 | M11: 1811 | N11: 1851 | O11: 2148 | P11: 3621 | Q11: 2924 | R11: 2994 | S11: 3522 | T11: 3091 | U11: 4204 | V11: 4308 | W11: 5190 | X11: 4389 | Y11: 6156 | Z11: 6285 | AA11: 7054 | AB11: 6413 | AC11: 417.56 | AD11: =AC11/100*10 -> 41.756 | AE11: =I11/100*10 -> 53.7
A12: 二 | B12: 设备及安装工程（万元） | C12: 16689 | D12: 15888 | E12: 16191 | F12: 17168 | G12: 30950 | H12: 31623 | I12: 33510 | J12: 60432 | K12: 60861 | L12: 64345 | M12: 147633 | N12: 149062 | O12: 158338 | P12: 289790 | Q12: 201613 | R12: 203100 | S12: 207586 | T12: 205824 | U12: 303998 | V12: 306225 | W12: 313072 | X12: 310469 | Y12: 582763 | Z12: 586513 | AA12: 597413 | AB12: 592813 | AC12: =SUM(AC13:AC18) -> 31128.82 | AD12: =AC12/100*10 -> 3112.882 | AE12: =I12/100*10 -> 3351
A13: 1 | B13: 发电场设备及安装工程（万元） | C13: 13277 | D13: 12558 | E13: 12395 | F13: 12535 | G13: 25116 | H13: 24791 | I13: 25071 | J13: 50231 | K13: 49581 | L13: 50141 | M13: 125579 | N13: 123954 | O13: 125354 | P13: 251157 | Q13: 129934 | R13: 131009 | S13: 134259 | T13: 132909 | U13: 220818 | V13: 222633 | W13: 228403 | X13: 226053 | Y13: 431216 | Z13: 434966 | AA13: 445866 | AB13: 441266 | AC13: 27197.17 | AD13: =AC13/100*10 -> 2719.717 | AE13: =I13/100*10 -> 2507.1
A14: 2 | B14: 集电线路设备及安装工程（万元） | C14: 2263 | D14: 1006 | E14: 1376 | F14: 2308 | G14: 2012 | H14: 2853 | I14: 4617 | J14: 5231 | K14: 6106 | L14: 9234 | M14: 13078 | N14: 15765 | O14: 24008 | P14: 26155 | AC14: 1961.88 | AD14: =AC14/100*10 -> 196.188 | AE14: =I14/100*10 -> 461.7
B15: 登陆海缆工程（万元） | C15: —— | D15: —— | E15: —— | F15: —— | G15: —— | H15: —— | I15: —— | J15: —— | K15: —— | L15: —— | M15: —— | N15: —— | O15: —— | P15: —— | Q15: 46431 | R15: 46843 | S15: 48079 | T15: 47667 | U15: 54078 | V15: 54490 | W15: 55567 | X15: 55314 | Y15: 106287 | Z15: 106287 | AA15: 106287 | AB15: 106287
A16: 3 | B16: 升压变电站设备及安装工程（万元） | C16: 1080 | D16: 2244 | E16: 2339 | F16: 2244 | G16: 3703 | H16: 3860 | I16: 3703 | J16: 4814 | K16: 5018 | L16: 4814 | M16: 8665 | N16: 9033 | O16: 8665 | P16: 12045 | Q16: 9571 | R16: 9571 | S16: 9571 | T16: 9571 | U16: 10898 | V16: 10898 | W16: 10898 | X16: 10898 | Y16: 20374 | Z16: 20374 | AA16: 20374 | AB16: 20374 | AC16: 1775.54 | AD16: =AC16/100*10 -> 177.554 | AE16: =I16/100*10 -> 370.3
B17: 陆上集控中心设备及安装工程（万元） | C17: —— | D17: —— | E17: —— | F17: —— | G17: —— | H17: —— | I17: —— | J17: —— | K17: —— | L17: —— | M17: —— | N17: —— | O17: —— | P17: —— | Q17: 7790 | R17: 7790 | S17: 7790 | T17: 7790 | U17: 9697 | V17: 9697 | W17: 9697 | X17: 9697 | Y17: 13404 | Z17: 13404 | AA17: 13404 | AB17: 13404
A18: 4 | B18: 其他设备及安装工程（万元） | C18: 69 | D18: 80 | E18: 80 | F18: 80 | G18: 120 | H18: 120 | I18: 120 | J18: 155 | K18: 155 | L18: 155 | M18: 311 | N18: 311 | O18: 311 | P18: 432 | Q18: 7887 | R18: 7887 | S18: 7887 | T18: 7887 | U18: 8507 | V18: 8507 | W18: 8507 | X18: 8507 | Y18: 11482 | Z18: 11482 | AA18: 11482 | AB18: 11482 | AC18: 194.23 | AD18: =AC18/100*10 -> 19.423 | AE18: =I18/100*10 -> 12
A19: 三 | B19: 建筑工程（万元） | C19: 3815 | D19: 2894 | E19: 4044 | F19: 4897 | G19: 5556 | H19: 7780 | I19: 9563 | J19: 11101 | K19: 14544 | L19: 18363 | M19: 28690 | N19: 35039 | O19: 45825 | P19: 60820 | Q19: 78963 | R19: 79108 | S19: 103588 | T19: 88018 | U19: 125399 | V19: 125541 | W19: 165028 | X19: 140886 | Y19: 222501 | Z19: 222855 | AA19: 298844 | AB19: 252050 | AC19: =SUM(AC20:AC26) -> 15303.7 | AD19: =AC19/100*10 -> 1530.37 | AE19: =I19/100*10 -> 956.3
A20: 1 | B20: 发电场工程（万元） | C20: 1752 | D20: 1336 | E20: 1650 | F20: 1627 | G20: 2672 | H20: 3364 | I20: 3354 | J20: 5345 | K20: 6379 | L20: 6858 | M20: 15811 | N20: 17797 | O20: 19591 | P20: 35223 | Q20: 53763 | R20: 53644 | S20: 75291 | T20: 62156 | U20: 93588 | V20: 93380 | W20: 131062 | X20: 108198 | Y20: 181203 | Z20: 180799 | AA20: 253758 | AB20: 209489 | AC20: 2254.22 | AD20: =AC20/100*10 -> 225.422 | AE20: =I20/100*10 -> 335.4
A21: 2 | B21: 集电线路工程（万元） | C21: 327 | D21: 214 | E21: 324 | F21: 370 | G21: 428 | H21: 649 | I21: 742 | J21: 1113 | K21: 1298 | L21: 1625 | M21: 2784 | N21: 3244 | O21: 4224 | P21: 5567 | AC21: 443.33 | AD21: =AC21/100*10 -> 44.333 | AE21: =I21/100*10 -> 74.2
A22: 3 | B22: 升压变电站工程（万元） | C22: 620 | D22: 736 | E22: 930 | F22: 933 | G22: 1215 | H22: 1452 | I22: 1466 | J22: 2168 | K22: 2938 | L22: 2948 | M22: 3852 | N22: 4698 | O22: 4952 | P22: 7547 | Q22: 12601 | R22: 12866 | S22: 15700 | T22: 13264 | U22: 16678 | V22: 17029 | W22: 18834 | X22: 17556 | Y22: 23989 | Z22: 24747 | AA22: 27777 | AB22: 25252 | AC22: 928.13 | AD22: =AC22/100*10 -> 92.813 | AE22: =I22/100*10 -> 146.6
B23: 登陆电缆工程（万元） | C23: —— | D23: —— | E23: —— | F23: —— | G23: —— | H23: —— | I23: —— | J23: —— | K23: —— | L23: —— | M23: —— | N23: —— | O23: —— | P23: —— | Q23: 3230 | R23: 3230 | S23: 3230 | T23: 3230 | U23: 4628 | V23: 4628 | W23: 4628 | X23: 4628 | Y23: 5178 | Z23: 5178 | AA23: 5178 | AB23: 5178
B24: 陆上集控中心工程 | C24: —— | D24: —— | E24: —— | F24: —— | G24: —— | H24: —— | I24: —— | J24: —— | K24: —— | L24: —— | M24: —— | N24: —— | O24: —— | P24: —— | Q24: 5590 | R24: 5590 | S24: 5590 | T24: 5590 | U24: 6028 | V24: 6028 | W24: 6028 | X24: 6028 | Y24: 6368 | Z24: 6368 | AA24: 6368 | AB24: 6368
A25: 5 | B25: 交通工程（万元） | C25: 595 | D25: 338 | E25: 770 | F25: 1598 | G25: 700 | H25: 1575 | I25: 3264 | J25: 1395 | K25: 2450 | L25: 5440 | M25: 3543 | N25: 5600 | O25: 13328 | P25: 5733 | Q25: 1450 | R25: 1450 | S25: 1450 | T25: 1450 | U25: 1450 | V25: 1450 | W25: 1450 | X25: 1450 | Y25: 1450 | Z25: 1450 | AA25: 1450 | AB25: 1450 | AC25: 8629.51 | AD25: =AC25/100*10 -> 862.951 | AE25: =I25/100*10 -> 326.4
A26: 6 | B26: 其他工程（万元） | C26: 520 | D26: 270 | E26: 370 | F26: 369 | G26: 540 | H26: 740 | I26: 736 | J26: 1080 | K26: 1480 | L26: 1492 | M26: 2700 | N26: 3700 | O26: 3730 | P26: 6750 | Q26: 2328 | R26: 2328 | S26: 2328 | T26: 2328 | U26: 3026 | V26: 3026 | W26: 3026 | X26: 3026 | Y26: 4313 | Z26: 4313 | AA26: 4313 | AB26: 4313 | AC26: 3048.51 | AD26: =AC26/100*10 -> 304.851 | AE26: =I26/100*10 -> 73.6
A27: 四 | B27: 其他费用（万元） | C27: 3575 | D27: 2837 | E27: 3604 | F27: 3593 | G27: 4964 | H27: 6487 | I27: 6192 | J27: 8697 | K27: 10534 | L27: 10226 | M27: 18847 | N27: 21824 | O27: 21290 | P27: 35795 | Q27: 29567 | R27: 30036 | S27: 32378 | T27: 30959 | U27: 42534 | V27: 43094 | W27: 44284 | X27: 43535 | Y27: 84484 | Z27: 85675 | AA27: 87978 | AB27: 86596 | AC27: =SUM(AC28:AC33) -> 6753.09 | AD27: =AC27/100*10 -> 675.309 | AE27: =I27/100*10 -> 619.2
A28: 1 | B28: 项目建设用地（海）费（万元） | C28: 950 | D28: 1000 | E28: 1000 | F28: 1000 | G28: 2000 | H28: 2000 | I28: 2000 | J28: 4000 | K28: 4000 | L28: 4000 | M28: 10000 | N28: 10000 | O28: 10000 | P28: 20000 | Q28: 10800 | R28: 10800 | S28: 10800 | T28: 10800 | U28: 18000 | V28: 18000 | W28: 18000 | X28: 18000 | Y28: 36000 | Z28: 36000 | AA28: 36000 | AB28: 36000 | AC28: 3543.07 | AD28: =AC28/100*10 -> 354.307 | AE28: =I28/100*10 -> 200
A29: 2 | B29: 项目前期费（万元） | C29: 200 | D29: 200 | E29: 200 | F29: 200 | G29: 400 | H29: 400 | I29: 400 | J29: 800 | K29: 800 | L29: 800 | M29: 2000 | N29: 2000 | O29: 2000 | P29: 4000 | Q29: 2000 | R29: 2000 | S29: 2000 | T29: 2000 | U29: 3500 | V29: 3500 | W29: 3500 | X29: 3500 | Y29: 4500 | Z29: 4500 | AA29: 4500 | AB29: 4500 | AC29: 500 | AD29: =AC29/100*10 -> 50 | AE29: =I29/100*10 -> 40
A30: 3 | B30: 项目建设管理费（万元） | C30: 1336 | D30: 811 | E30: 1259 | F30: 1288 | G30: 1238 | H30: 2115 | I30: 2007 | J30: 1807 | K30: 2866 | L30: 2780 | M30: 2945 | N30: 4643 | O30: 4504 | P30: 4859 | Q30: 10040 | R30: 10357 | S30: 11181 | T30: 10569 | U30: 11391 | V30: 11751 | W30: 12461 | X30: 11990 | Y30: 25527 | Z30: 26334 | AA30: 27677 | AB30: 26871 | AC30: 1883.1 | AD30: =AC30/100*10 -> 188.31 | AE30: =I30/100*10 -> 200.7
A31: 4 | B31: 生产准备费（万元） | C31: 311 | D31: 237 | E31: 307 | F31: 266 | G31: 362 | H31: 515 | I31: 414 | J31: 528 | K31: 698 | L31: 573 | M31: 861 | N31: 1131 | O31: 929 | P31: 1420 | Q31: 552 | R31: 564 | S31: 608 | T31: 575 | U31: 905 | V31: 924 | W31: 835 | X31: 943 | Y31: 1466 | Z31: 1496 | AA31: 1573 | AB31: 1527 | AC31: 440.37 | AD31: =AC31/100*10 -> 44.037 | AE31: =I31/100*10 -> 41.4
A32: 5 | B32: 科研勘察设计费（万元） | C32: 727 | D32: 446 | E32: 686 | F32: 697 | G32: 680 | H32: 1152 | I32: 1086 | J32: 993 | K32: 1561 | L32: 1505 | M32: 1618 | N32: 2529 | O32: 2437 | P32: 2670 | Q32: 6160 | R32: 6300 | S32: 7774 | T32: 7000 | U32: 8718 | V32: 8899 | W32: 9468 | X32: 9081 | Y32: 16966 | Z32: 17320 | AA32: 18203 | AB32: 17673 | AC32: 300 | AD32: =AC32/100*10 -> 30 | AE32: =I32/100*10 -> 108.6
A33: 6 | B33: 其他（万元） | C33: 52 | D33: 142 | E33: 152 | F33: 142 | G33: 285 | H33: 304 | I33: 284 | J33: 569 | K33: 608 | L33: 568 | M33: 1423 | N33: 1520 | O33: 1420 | P33: 2846 | Q33: 15 | R33: 15 | S33: 15 | T33: 15 | U33: 20 | V33: 20 | W33: 20 | X33: 20 | Y33: 25 | Z33: 25 | AA33: 25 | AB33: 25 | AC33: 86.55 | AD33: =AC33/100*10 -> 8.655 | AE33: =I33/100*10 -> 28.4
B34: 一至四部分合计（万元） | C34: 24617 | D34: 21941 | E34: 24378 | F34: 26280 | G34: 42108 | H34: 46930 | I34: 50468 | J34: 81493 | K34: 87921 | L34: 95280 | M34: 198328 | N34: 210317 | O34: 230781 | P34: 392722 | Q34: 316977 | R34: 319148 | S34: 350336 | T34: 331803 | U34: 480354 | V34: 483388 | W34: 531793 | X34: 503498 | Y34: 901445 | Z34: 906867 | AA34: 996830 | AB34: 943413 | AC34: =AC5+AC12+AC19+AC27 -> 54939.78 | AD34: =AC34/100*10 -> 5493.978 | AE34: =I34/100*10 -> 5046.8
A35: 五 | B35: 基本预备费（万元） | C35: 369 | D35: 329 | E35: 366 | F35: 394 | G35: 632 | H35: 704 | I35: 757 | J35: 1222 | K35: 1319 | L35: 1429 | M35: 2975 | N35: 3155 | O35: 3462 | P35: 5891 | Q35: 6340 | R35: 6383 | S35: 7007 | T35: 6636 | U35: 9607 | V35: 9668 | W35: 10636 | X35: 10070 | Y35: 18029 | Z35: 18137 | AA35: 19937 | AB35: 18868 | AC35: 824.1 | AD35: =AC35/100*10 -> 82.41 | AE35: =I35/100*10 -> 75.7
B36: 工程静态投资（万元） | C36: 24987 | D36: 22270 | E36: 24744 | F36: 26674 | G36: 42739 | H36: 47634 | I36: 51225 | J36: 82715 | K36: 89240 | L36: 96709 | M36: 201303 | N36: 213471 | O36: 234243 | P36: 398613 | Q36: 323316 | R36: 325531 | S36: 357342 | T36: 338439 | U36: 489961 | V36: 493056 | W36: 542429 | X36: 513568 | Y36: 919474 | Z36: 925005 | AA36: 1016767 | AB36: 962281 | AC36: =AC34+AC35 -> 55763.88 | AD36: =AC36/100*10 -> 5576.388 | AE36: =I36/100*10 -> 5122.5
A37: 六 | B37: 建设期贷款利息（万元）（3.95%） | C37: 395 | D37: 350 | E37: 389 | F37: 420 | G37: 673 | H37: 750 | I37: 806 | J37: 1302 | K37: 1404 | L37: 1522 | M37: 4743 | N37: 5029 | O37: 5519 | P37: 9391 | Q37: 5983 | R37: 6024 | S37: 6613 | T37: 6263 | U37: 9067 | V37: 9124 | W37: 10038 | X37: 9504 | Y37: 20418 | Z37: 20541 | AA37: 22578 | AB37: 21368
A38: 七 | B38: 工程动态总投资（万元） | C38: 25381 | D38: 22620 | E38: 25133 | F38: 27095 | G38: 43412 | H38: 48383 | I38: 52031 | J38: 84017 | K38: 90644 | L38: 98231 | M38: 206046 | N38: 218501 | O38: 239762 | P38: 408004 | Q38: 329299 | R38: 331555 | S38: 363955 | T38: 344701 | U38: 499028 | V38: 502180 | W38: 552467 | X38: 523072 | Y38: 939892 | Z38: 945545 | AA38: 1039345 | AB38: 983649
B39: 单位千瓦静态投资（元/kW) | C39: 4997 | D39: 4454 | E39: 4949 | F39: 5335 | G39: 4274 | H39: 4763 | I39: 5123 | J39: 4136 | K39: 4462 | L39: 4835 | M39: 4026 | N39: 4269 | O39: 4685 | P39: 3986 | Q39: 10777 | R39: 10851 | S39: 11911 | T39: 11281 | U39: 9799 | V39: 9861 | W39: 10849 | X39: 10271 | Y39: 9195 | Z39: 9250 | AA39: 10168 | AB39: 9623
B40: 单位千瓦动态投资（元/kW) | C40: 5076 | D40: 4524 | E40: 5027 | F40: 5419 | G40: 4341 | H40: 4838 | I40: 5203 | J40: 4201 | K40: 4532 | L40: 4912 | M40: 4121 | N40: 4370 | O40: 4795 | P40: 4080 | Q40: 10977 | R40: 11052 | S40: 12132 | T40: 11490 | U40: 9981 | V40: 10044 | W40: 11049 | X40: 10461 | Y40: 9399 | Z40: 9455 | AA40: 10393 | AB40: 9836
...

Sheet 04主要设备价格表
A1: 编号 | B1: 材料类别 | C1: 单位 | D1: 价格(含税)
A2: 一 | B2: 主要材料
A3: 1 | B3: 钢筋 | C3: 元/t | D3: 3800
A4: 2 | B4: 水泥42.5 | C4: 元/t | D4: 430
A5: 二 | B5: 陆上风电
A6: 1 | B6: 箱式变电站 | C6: 元/kVA | D6: 100
A7: 2 | B7: 主变压器 110kV 50MVA | C7: 万元/台 | D7: 200
A8: 3 | B8: 主变压器 110kV 100MVA | C8: 万元/台 | D8: 350
A9: 4 | B9: 主变压器 220kV 100MVA | C9: 万元/台 | D9: 580
A10: 5 | B10: 主变压器 220kV 170MVA | C10: 万元/台 | D10: 750
A11: 6 | B11: 高压开关柜 | C11: 万元/台 | D11: 18
A12: 7 | B12: 无功补偿装置 | C12: 元/kVar | D12: 50
A13: 三 | B13: 海上风电
A14: 1 | B14: 66kV 海底电缆 3×95mm2+2x36 芯光纤 | C14: 万元/km | D14: 110
A15: 2 | B15: 66kV 海底电缆 3×150mm2+2x36 芯光纤 | C15: 万元/km | D15: 135
A16: 3 | B16: 66kV 海底电缆 3×240mm2+2x36 芯光纤 | C16: 万元/km | D16: 165
A17: 4 | B17: 66kV 海底电缆 3×400mm2+2x36 芯光纤 | C17: 万元/km | D17: 245
A18: 5 | B18: 66kV 海底电缆 3×500mm2+2x36 芯光纤 | C18: 万元/km | D18: 285
A19: 6 | B19: 220kV 海底电缆 127/220kV,XLPE 绝缘,光电复合,钢丝铠装，3×500mm2+2×48 芯光纤 | C19: 万元/km | D19: 480
A20: 7 | B20: 220kV 海底电缆 127/220kV,XLPE 绝缘,光电复合,钢丝铠装，3×800mm2+2×48 芯光纤 | C20: 万元/km | D20: 580
A21: 8 | B21: 500kV 海底电缆 XLPE 绝缘,光电复合,钢丝铠装 3×800mm2+2×SM48C | C21: 万元/km | D21: 1250
A22: 9 | B22: 220kV 主变压器(海上)160MVA | C22: 万元/台 | D22: 970
A23: 10 | B23: 220kV 主变压器(海上)270MVA | C23: 万元/台 | D23: 1450
A24: 11 | B24: 500kV 主变压器(海上)550MVA | C24: 万元/台 | D24: 3000

Sheet 输入信息
A1: 序号 | B1: 指标 | C1: 原名称 | D1: 关键词 | E1: 辅助关键词 | F1: 是否必须 | G1: 是否think mode | H1: 温度设置 | I1: 选项 | J1: 数值 | K1: 单位
A2: 1 | B2: 直流侧装机容量或装机/规划容量 | C2: 直流侧装机容量 | D2: 直流侧装机容量、装机容量、规划容量、总容量 | E2: MWp | H2: 低 | K2: MWp
A3: 2 | B3: 交流侧装机容量 | C3: 交流侧装机容量 | D3: 交流侧容量、交流侧装机容量、MW、交流容量、建设装机容量、建设容量 | E3: MW | H3: 低 | K3: MW
A4: 3 | B4: 动态投资 | C4: 动态投资 | D4: 动态投资、动态总投资 | E4: 万 | H4: 低 | K4: 万元
A5: 4 | B5: 建设期利息 | C5: 建设期利息 | D5: 建设期利息 | E5: 万 | H5: 低 | K5: 万元
A6: 5 | B6: 建设/项目地的地形类型（请判断是平原还是山地） | C6: 地形 | D6: 地形、地貌、平原、山地、平缓、陡、鱼塘、渔塘 | E6: 建设地、拟建场地 | G6: 是 | H6: 低 | I6: 平原、山地 | K6: -
A7: 6 | B7: 配套储能费用 | C7: 配套储能 | D7: 配套储能、储能、储能工程 | E7: 万 | H7: 低 | K7: 万元
A8: 7 | B8: 送出线路及对端改造费用 | C8: 送出线路及对端改造 | D8: 送出线路、送出线路投资（含对侧间隔）、送出线路投资、对端改造、送出工程、送出 | E8: 万 | G8: 是 | H8: 低 | K8: 万元
A9: 8 | B9: 降水费用 | C9: 降水费用 | D9: 降水 | E9: 万 | F9: 是 | G9: 是 | H9: 低 | K9: 万元
A10: 9 | B10: 软基处理费 | C10: 软基处理费 | D10: 软基处理费、软基 | E10: 万 | F10: 是 | G10: 是 | H10: 低 | K10: 万元
A11: 10 | B11: 扶贫及乡村振兴 | C11: 扶贫及乡村振兴 | D11: 扶贫及乡村振兴、扶贫、乡村振兴、乡村 | E11: 万 | F11: 是 | G11: 是 | H11: 低 | K11: 万元
A12: 11 | B12: 生态治理、保护和恢复费 | C12: 沙漠生态治理 | D12: 沙漠、湿地 | E12: 万 | F12: 是 | G12: 是 | H12: 低 | K12: 万元
A13: 12 | B13: 反恐费用 | C13: 反恐费用 | D13: 反恐费用、反恐 | E13: 万 | F13: 是 | G13: 是 | H13: 低 | K13: 万元
A14: 13 | B14: 场外道路 | C14: 场外道路 | D14: 场外道路 | E14: 万 | F14: 是 | G14: 是 | H14: 低 | K14: 万元
A15: 14 | B15: 军民融合工程/军事补偿 | C15: 军民融合工程/军事补偿 | D15: 军民融合工程、军事补偿 | E15: 万 | F15: 是 | G15: 是 | H15: 低 | K15: 万元
A16: 15 | B16: 换填项目总额（50万元以上） | C16: 大方量基础换填 | D16: 换填 | E16: 万 | F16: 是 | G16: 是 | H16: 低 | K16: 万元
A17: 16 | B17: 本项目光伏组件设备价格 | C17: 本项目组件设备价格 | D17: 光伏组件设备、光伏组件 | F17: 是 | G17: 是 | H17: 中 | K17: 元/kW
A18: 17 | B18: 本项目逆变器设备价格 | C18: 本项目逆变器设备价格 | D18: 逆变器设备、逆变器 | F18: 是 | G18: 是 | H18: 中 | K18: 元/kW
A19: 18 | B19: 本项目固定支架/光伏组件支架重量 | C19: 本项目固定支架重量 | D19: 固定支架、光伏组件支架 | E19: t | F19: 是 | H19: 中 | K19: t
A20: 19 | B20: 固定可调支架对应容量 | C20: 固定可调支架对应容量 | D20: 固定可调支架容量、固定可调容量、固定可调支架 | E20: MWp | F20: 是 | H20: 中 | K20: MWp
A21: 20 | B21: 平单轴跟踪支架对应容量 | C21: 平单轴跟踪支架对应容量 | D21: 平单轴跟踪支架容量、平单轴容量、平单轴支架容量、平单轴跟踪支架、平单轴、平单轴支架 | E21: MWp | F21: 是 | H21: 中 | K21: MWp
A22: 21 | B22: 柔性支架对应容量 | C22: 柔性支架对应容量 | D22: 柔性支架容量、柔性容量、柔性支架 | E22: MWp | F22: 是 | H22: 中 | K22: MWp
A23: 22 | B23: 判断项目采用的逆变器类型 | C23: 逆变器类型 | D23: 组串式逆变器、集中式逆变器 | E23: 选用 | H23: 中 | I23: 组串式逆变器、集中式逆变器、分布式逆变器 | K23: -
A24: 23 | B24: 发电场工程PHC桩或预应力高强度混凝土管桩（桩径300 mm）总长度 | C24: PHC桩（桩径φ300） | D24: PHC、预应力高强度混凝土、预应力混凝土、预应力管桩、预应力 | E24: 300 | F24: 是 | G24: 是 | H24: 高 | K24: m
A25: 24 | B25: 直流侧装机容量或装机/规划容量 | C25: PHC桩（桩径φ300）对应容量 | D25: 直流侧装机容量、装机容量、规划容量、总容量 | H25: 低 | K25: MWp
A26: 25 | B26: 发电场工程PHC桩或预应力高强度混凝土管桩（桩径400 mm）总长度 | C26: PHC桩（桩径φ400） | D26: PHC、预应力高强度混凝土、预应力混凝土、预应力管桩、预应力 | E26: 400 | F26: 是 | G26: 是 | H26: 高 | K26: m
A27: 26 | B27: 发电场工程灌注桩（桩径250 mm）总长度 | C27: 灌注桩（桩径φ250） | D27: 灌注 | E27: 250 | F27: 是 | G27: 是 | H27: 高 | K27: m
A28: 27 | B28: 发电场工程灌注桩（桩径300 mm）总长度 | C28: 灌注桩（桩径φ300） | D28: 灌注 | E28: 300 | F28: 是 | G28: 是 | H28: 高 | K28: m
A29: 28 | B29: 发电场工程灌注桩（桩径350 mm）总长度 | C29: 灌注桩（桩径φ350） | D29: 灌注 | E29: 350 | F29: 是 | G29: 是 | H29: 高 | K29: m
A30: 29 | B30: 发电场工程灌注桩（桩径400 mm）总长度 | C30: 灌注桩（桩径φ400） | D30: 灌注 | E30: 400 | F30: 是 | G30: 是 | H30: 高 | K30: m
A31: 30 | B31: 发电场工程螺旋桩总长度 | C31: 螺旋桩 | D31: 螺旋 | F31: 是 | G31: 是 | H31: 高 | K31: m
A32: 31 | B32: 是否有农林光伏 | C32: 农林光伏 | D32: 农林光伏、种菜、农、林、渔业、渔 | G32: 是 | H32: 中 | I32: 是、否 | K32: -
A33: 32 | B33: 是否有渔光互补 | C33: 渔光互补 （特指采用预制桩基础形式） | D33: 渔光互补、渔业、渔、农业、农 | G33: 是 | H33: 中 | I33: 是、否 | K33: -
A34: 33 | B34: 是否有水面光伏 （特指漂浮式光伏） | C34: 水面光伏 （特指漂浮式光伏） | D34: 水面光伏、漂浮 | H34: 中 | I34: 是、否 | K34: -
A35: 34 | B35: 是否有滩涂光伏（海边） | C35: 滩涂光伏（海边） | D35: 滩涂光伏、海边、滩涂 | H35: 中 | I35: 是、否 | K35: -
A36: 35 | B36: 新建、配套建设升压站（变电站）电压等级 | C36: 变压器电压等级 | D36: 升压站、变电站、开关站 | E36: 新建 | H36: 中
A37: 36 | B37: 变压器能耗是否为一级或1级 | C37: 变压器能耗（一级） | D37: 一级、1级 | F37: 是 | H37: 低 | I37: 是、否 | K37: -
A38: 37 | B38: 道路新建长度 | C38: 道路新建长度 | D38: 道路新建、新建道路 | E38: km | F38: 是 | H38: 低 | K38: km
A39: 38 | B39: 道路改扩建长度 | C39: 道路改扩建长度 | D39: 道路改扩建、道路改建、道路扩改建、道路扩建、改扩建道路、改建道路、扩建道路 | E39: km | F39: 是 | H39: 低 | K39: km
A40: 39 | B40: 建设用地费 | C40: 建设用地费 | D40: 建设用地 | E40: 万 | F40: 是 | H40: 低 | K40: 万元
...

Sheet 集中式光伏造价标准调整（2025版）
A1: 1）基准值为动态投资对应的千瓦造价，以直流侧装机规模计算； 2）集中式电站装机规模低于60MWp（直流侧）的以50MW（60MWp）基准值为准，高于1200MWp（直流侧）的以1000MW（1200MWp）基准值为准，其他按直流侧装机利用线性插值法按比例调整
A2: 序号 | B2: 项目名称 | C2: 单位 | D2: 集中式光伏 | I2: 造价调整值（元/kW） | J2: 直流侧装机容量（MWp） | K2: =输入信息!J2 -> 0 | L2: 单位千瓦动态投资（元/kWp） | M2: =I5 -> 地形 | N2: 研究院复核-与造价标准值可比投资（万元）（总投资-配套储能、送出、其他投资） | O2: 研究院复核-与造价标准值可比投资（元/kWp）（总投资-配套储能、送出、其他投资） | P2: 研究院复核-集团公司下发的造价标准值（元/kWp） （标准值+调整值） | Q2: 超标百分比 | R2: 研究院复核-如果单位千瓦造价超标准值，要说明原因 | S2: 项目单位原因说明
C3: 交流侧（MW） | D3: 50 | E3: 100 | F3: 200 | G3: 500 | H3: 1000 | I3: =SUM(I4:I48) -> #DIV/0! | J3: 交流测装机容量（MW） | K3: =输入信息!J3 -> 0 | L3: =K4/K2*10 -> #DIV/0! | M3: =I6 -> 0 | N3: =K4-K6-K8 -> #DIV/0! | O3: =N3/K2*10 -> #DIV/0! | P3: =I3 -> #DIV/0! | Q3: =(O3-P3)/P3 -> #DIV/0! | R3: =IF(Q3>=0%,"超标","未超标") -> #DIV/0!
C4: 直流侧（MWp） | D4: 60 | E4: 120 | F4: 240 | G4: 600 | H4: 1200 | J4: 动态投资（万元） | K4: =输入信息!J4 -> 0
A5: 1 | B5: 基本方案千瓦造价标准值 | I5: 地形 | J5: 建设期利息（万元） | K5: =输入信息!J5 -> 0
A6: 1.1 | B6: 平原 | C6: 元/kWp | D6: 2581 | E6: 2433 | F6: 2416 | G6: 2353 | H6: 2334 | I6: =输入信息!J6 -> 0 | J6: 其他扣除费用对应建设期利息（万元） | K6: =K8/(K4-K5)*K5 -> #DIV/0!
A7: 1.2 | B7: 山地 | C7: 元/kWp | D7: 2730 | E7: 2585 | F7: 2568 | G7: 2500 | H7: 2483 | I7: =IF(I6="平原",IF(K2<60,D6,IF(K2>1200,H6,INDEX(D6:H6,MATCH(K2,D4:H4,1))+(INDEX(D6:H6,MATCH(K2,D4:H4,1)+1)-INDEX(D6:H6,MATCH(K2,D4:H4,1)))*(K2-INDEX(D4:H4,MATCH(K2,D4:H4,1)))/(INDEX(D4:H4,MATCH(K2,D4:H4,1)+1)-INDEX(D4:H4,MATCH(K2,D4:H4,1))))),IF(K2<60,D7,IF(K2>1200,H7,INDEX(D7:H7,MATCH(K2,D4:H4,1))+(INDEX(D7:H7,MATCH(K2,D4:H4,1)+1)-INDEX(D7:H7,MATCH(K2,D4:H4,1)))*(K2-INDEX(D4:H4,MATCH(K2,D4:H4,1)))/(INDEX(D4:H4,MATCH(K2,D4:H4,1)+1)-INDEX(D4:H4,MATCH(K2,D4:H4,1)))))) -> 2730 | L7: 配套储能 （万元） | M7: 送出线路及对端改造（万元） | N7: 降水费用（万元） | O7: 软基处理费（万元） | P7: 扶贫及乡村振兴（万元） | Q7: 沙漠生态治理（万元） | R7: 反恐费用(万元） | S7: 其他扣除（万元） | T7: 军民融合工程/军事补偿（万元） | U7: 大方量基础换填（50万元以上）
A8: 2 | B8: 千瓦造价调整模块 | J8: 其他扣除费用合计（万元） | K8: =SUM(L8:U8) -> 0 | L8: =输入信息!J7 -> 0 | M8: =输入信息!J8 -> 0 | N8: =输入信息!J9 -> 0 | O8: =输入信息!J10 -> 0 | P8: =输入信息!J11 -> 0 | Q8: =输入信息!J12 -> 0 | R8: =输入信息!J13 -> 0 | S8: =输入信息!J14 -> 0 | T8: =输入信息!J15 -> 0 | U8: =输入信息!J16 -> 0
A9: 2.1 | B9: 设备价格调整
A10: 2.1.1 | B10: 组件设备价格 | C10: 元/kWp | D10: 以实际价格替代（光伏组件设备650元/kWp） | I10: =L10-650 -> -650 | K10: 组件价格（元/kWp） | L10: =输入信息!J17 -> 0 | M10: 集团最新集采价：P型0.67 元/Wp、N型TOPCon 0.75元/Wp、HJT和BC 0.82 元/Wp； 组串式0.12元/W、集中式0.17元/W、分布式光伏逆变器0.15 元/W
A11: 2.1.2 | B11: 逆变器价格调整 | C11: 元/kW | D11: 以实际价格替代（逆变器设备110元/kW） | I11: =(L11-110)*$K$3/$K$2 -> #DIV/0! | K11: 逆变器设备价格（元/kW） | L11: =输入信息!J18 -> 0 | M11: 【注】组件逆变器价格不高于最近一期集团集采价格
A12: 2.2 | B12: 支架调整
A13: 2.2.1 | B13: 固定支架 | C13: t | D13: 以实际重量替代（6500元/t） | I13: =(K15-K17)*6500/10000/$K$2*10 -> #DIV/0! | K13: 固定支架实际重量调整
A14: 2.2.2 | B14: 固定可调支架 | C14: 元/kWp | D14: 60 | E14: 58 | F14: 56 | G14: 53 | H14: 50 | I14: =IF(M15<60,D14,IF(M15>1200,H14,INDEX(D14:H14,MATCH(K2,D4:H4,1))+(INDEX(D14:H14,MATCH(K2,D4:H4,1)+1)-INDEX(D14:H14,MATCH(K2,D4:H4,1)))*(K2-INDEX(D4:H4,MATCH(K2,D4:H4,1)))/(INDEX(D4:H4,MATCH(K2,D4:H4,1)+1)-INDEX(D4:H4,MATCH(K2,D4:H4,1)))))*M15/K2 -> #DIV/0! | K14: 实际固定支架（t） | L14: 固定支架装机容量（MWp） | M14: 固定可调支架装机容量（MWp） | N14: 平单轴跟踪支架装机容量（MWp） | O14: 柔性支架装机容量（MWp）
A15: 2.2.3 | B15: 平单轴跟踪支架 | C15: 元/kWp | D15: 160 | E15: 155 | F15: 150 | G15: 135 | H15: 130 | I15: =IF(N15<60,D15,IF(N15>1200,H15,INDEX(D15:H15,MATCH(K2,D4:H4,1))+(INDEX(D15:H15,MATCH(K2,D4:H4,1)+1)-INDEX(D15:H15,MATCH(K2,D4:H4,1)))*(K2-INDEX(D4:H4,MATCH(K2,D4:H4,1)))/(INDEX(D4:H4,MATCH(K2,D4:H4,1)+1)-INDEX(D4:H4,MATCH(K2,D4:H4,1)))))*N15/K2 -> #DIV/0! | K15: =输入信息!J19 -> 0 | L15: =K2-M15-N15-O15 -> 0 | M15: =输入信息!J20 -> 0 | N15: =输入信息!J21 -> 0 | O15: =输入信息!J22 -> 0
A16: 2.2.4 | B16: 柔性支架 | C16: 元/kWp | D16: 400 | E16: 380 | F16: 360 | G16: 340 | H16: 320 | I16: =IF(O15<60,D16,IF(O15>1200,H16,INDEX(D16:H16,MATCH(K2,D4:H4,1))+(INDEX(D16:H16,MATCH(K2,D4:H4,1)+1)-INDEX(D16:H16,MATCH(K2,D4:H4,1)))*(K2-INDEX(D4:H4,MATCH(K2,D4:H4,1)))/(INDEX(D4:H4,MATCH(K2,D4:H4,1)+1)-INDEX(D4:H4,MATCH(K2,D4:H4,1)))))*O15/K2 -> #DIV/0! | K16: 固定支架标准值（t）
A17: 2.3 | B17: 逆变器调整 | K17: =L15/15*544 -> 0
A18: 2.3.1 | B18: 集中式逆变器（调减） | C18: 元/kWp | D18: -30 | I18: =IF(K20="集中式逆变器",D18,0) -> 0
A19: 2.4 | B19: 基础建安费调整 | C19: 根据实际长度调整 | K19: 实际类型 | L19: 基本方案
D20: 平原 | G20: 山地 | K20: =输入信息!J23 -> 0 | L20: 组串式逆变器
A21: 2.4.1 | B21: PHC桩（桩径φ300） | C21: 元/m | D21: 135 | G21: 155 | I21: =IF(O35="否",(L24-N24)*IF(I$6="平原",D21,G21)/10000/$K$2*10,0) -> 0
A22: 2.4.2 | B22: PHC桩（桩径φ400） | C22: 元/m | D22: 150 | G22: 170 | I22: =IF(O35="否",IF(I$6="平原",D22,G22)/10000*L25/$K$2*10,0) -> 0 | K22: 桩实际长度调整
A23: 2.4.3 | B23: 灌注桩（桩径φ250） | C23: 元/m | D23: 150 | G23: 185 | I23: =IF(O35="否",IF(I$6="平原",D23,G23)/10000*L26/$K$2*10,0) -> 0 | K23: 实际桩类型 | L23: 实际桩长（m） | M23: 装机容量（MWp） | N23: 标准值（m）
A24: 2.4.4 | B24: 灌注桩（桩径φ300） | C24: 元/m | D24: 200 | G24: 240 | I24: =IF(O35="否",IF(I$6="平原",D24,G24)/10000*L27/$K$2*10,0) -> 0 | K24: 基本方案：预应力混凝土桩（PHC 300 AB 70） | L24: =输入信息!J24 -> 0 | M24: =输入信息!J25 -> 0 | N24: =M24/24*31533 -> 0 | O24: 【注】基础方案中支架基础为预应力混凝土桩（PHC 300 AB 70），实际方案调整此项！
A25: 2.4.5 | B25: 灌注桩（桩径φ350） | C25: 元/m | D25: 250 | G25: 310 | I25: =IF(O35="否",IF(I$6="平原",D25,G25)/10000*L28/$K$2*10,0) -> 0 | K25: PHC桩（桩径φ400） | L25: =输入信息!J26 -> 0
A26: 2.4.6 | B26: 灌注桩（桩径φ400） | C26: 元/m | D26: 300 | G26: 390 | I26: =IF(O35="否",IF(I$6="平原",D26,G26)/10000*L29/$K$2*10,0) -> 0 | K26: 灌注桩（桩径φ250） | L26: =输入信息!J27 -> 0
A27: 2.4.7 | B27: 螺旋桩 | C27: 元/m | D27: 126 | G27: 146 | I27: =IF(O35="否",IF(I$6="平原",D27,G27)/10000*L30/$K$2*10,0) -> 0 | K27: 灌注桩（桩径φ300） | L27: =输入信息!J28 -> 0
A28: 2.5 | B28: 农林光伏 | C28: 元/kWp | D28: 68 | I28: =IF(K35="是",D28,0) -> 0 | K28: 灌注桩（桩径φ350） | L28: =输入信息!J29 -> 0
A29: 2.6 | B29: 渔光互补 （特指采用预制桩基础形式） | C29: 元/kWp | D29: 189 | I29: =IF(L35="是",D29,0) -> 0 | K29: 灌注桩（桩径φ400） | L29: =输入信息!J30 -> 0
A30: 2.7 | B30: 水面光伏 （特指漂浮式光伏） | C30: 元/kWp | D30: 264 | I30: =IF(M35="是",D30,0) -> 0 | K30: 螺旋桩 | L30: =输入信息!J31 -> 0
A31: 2.8 | B31: 滩涂光伏（海边） | C31: 元/kWp | D31: 290 | I31: =IF(N35="是",D31,0) -> 0
A32: 2.9 | B32: 变电站调整 | K32: 【注】农林光伏、渔光互补、滩涂光伏（海边）调整值均已包含桩基础调整费用，不再重复调整。
A33: 2.9.1 | B33: 220kV升压站 | C33: 元/kWp | D33: 122 | E33: 81 | F33: 0 | G33: 0 | H33: 27 | I33: =IF(K38="220kV",IF(K2<60,D33,IF(K2>1200,H33,INDEX(D33:H33,MATCH(K2,D4:H4,1))+(INDEX(D33:H33,MATCH(K2,D4:H4,1)+1)-INDEX(D33:H33,MATCH(K2,D4:H4,1)))*(K2-INDEX(D4:H4,MATCH(K2,D4:H4,1)))/(INDEX(D4:H4,MATCH(K2,D4:H4,1)+1)-INDEX(D4:H4,MATCH(K2,D4:H4,1))))),0) -> 0 | K33: 农林光伏、渔光互补、水面光伏、滩涂光伏（海边）调整
A34: 2.9.2 | B34: 330kV升压站 | C34: 元/kWp | D34: - | E34: - | F34: 82 | G34: 29 | H34: 0 | I34: =IF(K38="330kV",IF(K2<240,F34,IF(K2>1200,H34,INDEX(F34:H34,MATCH(K2,F4:H4,1))+(INDEX(F34:H34,MATCH(K2,F4:H4,1)+1)-INDEX(F34:H34,MATCH(K2,F4:H4,1)))*(K2-INDEX(F4:H4,MATCH(K2,F4:H4,1)))/(INDEX(F4:H4,MATCH(K2,F4:H4,1)+1)-INDEX(F4:H4,MATCH(K2,F4:H4,1))))),0) -> 0 | K34: 农林光伏 | L34: 渔光互补 | M34: 水面光伏 | N34: 滩涂光伏（海边） | O34: 是否涉及此项
A35: 2.9.3 | B35: 变压器能耗(一级） | C35: 元/kWp | D35: 6 | I35: =IF(L38="是",D35,0) -> 0 | K35: =输入信息!J32 -> 0 | L35: =输入信息!J33 -> 0 | M35: =输入信息!J34 -> 0 | N35: =输入信息!J35 -> 0 | O35: =IF(AND(K35="否",L35="否",M35="否",N35="否"),"否","是") -> 是
A36: 2.1 | B36: 交通工程调整 | C36: 根据道路实际长度调整
D37: 平原 | G37: 山地 | K37: 变压器类型 | L37: 变压器能耗(一级）
A38: 2.10.1 | B38: 新建 | C38: 元/km | D38: 280000 | G38: 400000 | I38: =(L42-M42*IF(I$6="平原",1,2))*IF(I$6="平原",D38,G38)/10000/$K$2*10 -> #DIV/0! | K38: =输入信息!J36 -> 0 | L38: =输入信息!J37 -> 0
A39: 2.10.2 | B39: 改扩建 | C39: 元/km | D39: 100000 | G39: 250000 | I39: =K42*IF(I$6="平原",D39,G39)/10000/$K$2*10 -> #DIV/0!
A40: 2.11 | B40: 容配比调整 | C40: 元/kWp | D40: 50 | I40: =(1.2-IF(L45>1.2,1.2,IF(L45<1,1,L45)))/(1.2-1)*D40 -> #DIV/0! | K40: 道路调整
...

Sheet 12基本方案（2025版）
A1: 序号 | B1: 名称 | C1: 基本方案说明
B2: 工程类别 | C2: 地面光伏 | H2: 工商业光伏 | I2: 户用光伏
B3: 并网容量（MW） | C3: 50 | D3: 100 | E3: 200 | F3: 500 | G3: 1000 | H3: 5 | I3: 82.5
B4: 直流侧容（MWp） | C4: 60 | D4: 120 | E4: 240 | F4: 600 | G4: 1200 | H4: 6 | I4: 100
A5: 一 | B5: 组件型号 | C5: N型Topcon双面双玻（182型）600+Wp
A6: 二 | B6: 组件支架 | C6: （1）固定钢支架 | H6: （1）固定钢支架
C7: （2）支架总量2176t | D7: （2）支架总量4352t | E7: （2）支架总量8704t | F7: （2）支架总量21760t | G7: （2）支架总量43520t | H7: （2）支架总量180t | I7: （2）支架总量3000t
A8: 三 | B8: 支架基础 | C8: (1)预应力混凝土桩（PHC 300 AB 70） | H8: （1）混凝土预制压块
C9: (2)桩总长78833m | D9: (2)桩总长157665m | E9: (2)桩总长315330m | F9: (2)桩总长788325m | G9: (2)桩总长1576650m | H9: （2）预制压块体积156m3 | I9: （2）预制压块体积2600m3
A10: 四 | B10: 汇流及配电设备 | C10: 组串式逆变器320kW，3150kVA箱变,箱式变压器基础采用现浇钢筋混凝土箱型结构，混凝土强度等级为C30，天然地基 | H10: 组串式逆变器320kW，3150kVA箱变 | I10: 组串式逆变器平均功率16.5kW，0.4kV并网箱，监控系统无调度功能
A11: 五 | B11: 集电线路 | C11: 35kV铝合金地埋电缆17.5km | D11: 35kV铝合金地埋电缆35km | E11: 35kV铝合金地埋电缆70km | F11: 35kV铝合金地埋电缆175km | G11: 35kV铝合金地埋电缆350km | H11: 铝合金电缆桥架敷设，3km 10kV电缆 | I11: PVC穿线管
A12: 六 | B12: 升压站/开关站 | C12: （1）站内动力电缆采用铜芯电缆 （2）站内道路采用4.5m水泥混凝土路面，转弯半径为9m；站内电缆沟采用钢筋混凝土结构 （3）升压站基础均为天然地基，综合楼及附属用房均采用常规建筑型式，电气室采用预制舱形式 | H12: 10kV接入 | I12: 并网箱出线并入变压器低压侧380V母线
C13: （4）配套新建一座110kV升压站，配置1台50MVA主变 | D13: （4）配套新建一座110kV升压站，配置1台100MVA主变 | E13: （4）配套新建一座220kV升压站，配置2台100MVA主变 | F13: （4）配套新建一座220kV升压站，配置2台250MVA主变 | G13: （4）配套新建一座330kV升压站，配置4台250MVA主变
A14: 七 | B14: 交通工程/房屋加固 | C14: （1）进站道路采用水泥混凝土路面，路面宽4m，路基宽5m （2）场区道路泥结石路面 | H14: 不含房屋加固工程
C15: （3）新建场区道路，其中平原8.1km，山地16.2km | D15: （3）新建场区道路，其中平原16.2km，山地32.4km | E15: （3）新建场区道路，其中平原32.4km，山地64.8km | F15: （3）新建场区道路，其中平原81km，山地162km | G15: （3）新建场区道路，其中平原162km，山地324km | H15: 必要的道路修建与维护 | I15: -

Sheet 13造价参考值（2025版）
A1: 容量（MW） | C1: 50MW | E1: 100MW | G1: 200MW | I1: 500MW | K1: 1000MW | M1: 分布式
A2: 序号 | B2: 项目名称/地形 | C2: 平原 | D2: 山地 | E2: 平原 | F2: 山地 | G2: 平原 | H2: 山地 | I2: 平原 | J2: 山地 | K2: 平原 | L2: 山地 | M2: 工商业 | N2: 户用
A3: 一 | B3: 设备及安装工程（万元） | C3: 10305 | D3: 10571 | E3: 19743 | F3: 20314 | G3: 39213 | H3: 40355 | I3: 96106 | J3: 98593 | K3: 189445 | L3: 194502 | M3: 1216 | N3: 19535
A4: 1 | B4: 发电场设备及安装工程（万元） | C4: 8573 | D4: 8839 | E4: 17145 | F4: 17717 | G4: 34291 | H4: 35433 | I4: 85727 | J4: 88214 | K4: 171455 | L4: 176513 | M4: 986 | N4: 16541
A5: 2 | B5: 升压变电站设备及安装工程（万元） | C5: 864 | D5: 864 | E5: 1289 | F5: 1289 | G5: 2527 | H5: 2527 | I5: 5356 | J5: 5356 | K5: 9535 | L5: 9535 | M5: 73 | N5: 450
A6: 3 | B6: 控制保护设备及安装工程（万元） | C6: 588 | D6: 588 | E6: 878 | F6: 878 | G6: 1721 | H6: 1721 | I6: 3649 | J6: 3649 | K6: 6496 | L6: 6496 | M6: 127 | N6: 1659
A7: 4 | B7: 其他设备及安装工程（万元） | C7: 101 | D7: 101 | E7: 150 | F7: 150 | G7: 294 | H7: 294 | I7: 623 | J7: 623 | K7: 1109 | L7: 1109 | M7: 15 | N7: 605
A8: 5 | B8: 智慧化场站（万元） | C8: 180 | D8: 180 | E8: 280 | F8: 280 | G8: 380 | H8: 380 | I8: 750 | J8: 750 | K8: 850 | L8: 850 | M8: 15 | N8: 280
A9: 二 | B9: 建筑工程（万元） | C9: 2338 | D9: 2917 | E9: 4304 | F9: 5462 | G9: 8566 | H9: 10882 | I9: 20637 | J9: 26425 | K9: 40317 | L9: 51895 | M9: 79 | N9: 1184
A10: 1 | B10: 发电场工程（万元） | C10: 1402 | D10: 1560 | E10: 2805 | F10: 3120 | G10: 5609 | H10: 6240 | I10: 14023 | J10: 15600 | K10: 28046 | L10: 31199 | M10: 51 | N10: 474
A11: 2 | B11: 升压变电站工程（万元） | C11: 145 | D11: 145 | E11: 216 | F11: 216 | G11: 424 | H11: 424 | I11: 899 | J11: 899 | K11: 1600 | L11: 1600 | M11: 13 | N11: 168
A12: 3 | B12: 房屋建筑工程（万元） | C12: 387 | D12: 387 | E12: 570 | F12: 570 | G12: 1116 | H12: 1116 | I12: 2367 | J12: 2367 | K12: 4213 | L12: 4213 | M12: 0 | N12: 75
A13: 4 | B13: 交通工程（万元） | C13: 227 | D13: 648 | E13: 454 | F13: 1296 | G13: 907 | H13: 2592 | I13: 2268 | J13: 6480 | K13: 4536 | L13: 12960 | M13: 5 | N13: 100
A14: 5 | B14: 其他工程（万元） | C14: 177 | D14: 177 | E14: 260 | F14: 260 | G14: 510 | H14: 510 | I14: 1080 | J14: 1080 | K14: 1923 | L14: 1923 | M14: 10 | N14: 367
A15: 三 | B15: 其他费用（万元） | C15: 2428 | D15: 2457 | E15: 4167 | F15: 4209 | G15: 8257 | H15: 8339 | I15: 18744 | J15: 18909 | K15: 37189 | L15: 37512 | M15: 194 | N15: 3001
A16: 1 | B16: 项目建设用地费（万元） | C16: 1000 | D16: 1000 | E16: 2000 | F16: 2000 | G16: 4000 | H16: 4000 | I16: 10000 | J16: 10000 | K16: 20000 | L16: 20000 | M16: 0 | N16: 0
A17: 2 | B17: 项目建设管理费（万元） | C17: 1188 | D17: 1216 | E17: 1747 | F17: 1789 | G17: 3424 | H17: 3506 | I17: 6847 | J17: 7012 | K17: 13421 | L17: 13744 | M17: 146 | N17: 1934
A18: 3 | B18: 生产准备费（万元） | C18: 82 | D18: 82 | E18: 120 | F18: 120 | G18: 235 | H18: 235 | I18: 471 | J18: 471 | K18: 922 | L18: 922 | M18: 8 | N18: 217
A19: 4 | B19: 勘察设计费（万元） | C19: 125 | D19: 125 | E19: 250 | F19: 250 | G19: 500 | H19: 500 | I19: 1250 | J19: 1250 | K19: 2500 | L19: 2500 | M19: 25 | N19: 300
A20: 5 | B20: 其他税费（万元） | C20: 34 | D20: 34 | E20: 50 | F20: 50 | G20: 98 | H20: 98 | I20: 176 | J20: 176 | K20: 346 | L20: 346 | M20: 15 | N20: 550
B21: 一至三部分合计（万元） | C21: 15072 | D21: 15945 | E21: 28214 | F21: 29985 | G21: 56036 | H21: 59576 | I21: 135488 | J21: 143927 | K21: 266951 | L21: 283909 | M21: 1489 | N21: 23720
A22: 四 | B22: 基本预备费（万元） | C22: 301 | D22: 319 | E22: 564 | F22: 600 | G22: 1121 | H22: 1192 | I22: 2710 | J22: 2879 | K22: 5339 | L22: 5678 | M22: 30 | N22: 474
B23: 工程静态投资（万元） | C23: 15373 | D23: 16264 | E23: 28778 | F23: 30584 | G23: 57157 | H23: 60768 | I23: 138197 | J23: 146806 | K23: 272290 | L23: 289587 | M23: 1519 | N23: 24194
A24: 五 | B24: 价差预备费（万元） | C24: 0 | D24: 0 | E24: 0 | F24: 0 | G24: 0 | H24: 0 | I24: 0 | J24: 0 | K24: 0 | L24: 0 | M24: 0 | N24: 0
B25: 建设投资（万元） | C25: 15373 | D25: 16264 | E25: 28778 | F25: 30584 | G25: 57157 | H25: 60768 | I25: 138197 | J25: 146806 | K25: 272290 | L25: 289587 | M25: 1519 | N25: 24194
A26: 五 | B26: 建设期贷款利息（万元） | C26: 111 | D26: 117 | E26: 414 | F26: 440 | G26: 823 | H26: 875 | I26: 2985 | J26: 3171 | K26: 7842 | L26: 8340 | M26: 5 | N26: 174
A27: 六 | B27: 工程动态总投资（万元） | C27: 15484 | D27: 16381 | E27: 29192 | F27: 31025 | G27: 57980 | H27: 61643 | I27: 141182 | J27: 149977 | K27: 280132 | L27: 297928 | M27: 1525 | N27: 24368
B28: 直流侧单位千瓦静态投资（元/kW) | C28: 2562 | D28: 2711 | E28: 2398 | F28: 2549 | G28: 2382 | H28: 2532 | I28: 2303 | J28: 2447 | K28: 2269 | L28: 2413 | M28: 2532 | N28: 2419
B29: 直流侧单位千瓦动态投资（元/kW) | C29: 2581 | D29: 2730 | E29: 2433 | F29: 2585 | G29: 2416 | H29: 2568 | I29: 2353 | J29: 2500 | K29: 2334 | L29: 2483 | M29: 2541 | N29: 2437

Sheet 14主要设备价格表（2025版）
A1: 编号 | B1: 设备类别 | C1: 单位 | D1: 价格(含税)
A2: 1 | B2: 组件 | C2: 元/Wp | D2: 0.65
A3: 2 | B3: 逆变器 | C3: 元/W | D3: 0.11
A4: 3 | B4: 箱式变电站 | C4: 元/kVA | D4: 100
A5: 4 | B5: 主变压器110kV 50MVA | C5: 万元/台 | D5: 200
A6: 5 | B6: 主变压器110kV 100MVA | C6: 万元/台 | D6: 350
A7: 6 | B7: 主变压器220kV 100MVA | C7: 万元/台 | D7: 580
A8: 7 | B8: 主变压器220kV 250MVA | C8: 万元/台 | D8: 800
A9: 8 | B9: 高压开关柜 | C9: 万元/台 | D9: 18
A10: 9 | B10: 无功补偿装置 | C10: 元/kVar | D10: 50
A11: 备注：如项目选取规格与上述不同，可参照相近或类似条目，变压器为二级能效。
A13: 编号 | B13: 材料类别 | C13: 单位 | D13: 价格(含税)
A14: 1 | B14: 固定支架 | C14: 元/t | D14: 6500
A15: 2 | B15: 铝合金导轨 | C15: 元/t | D15: 22000
A16: 3 | B16: 钢筋 | C16: 元/t | D16: 3800
A17: 4 | B17: 水泥42.5 | C17: 元/t | D17: 430
